Workbook

Sheet Low
A1: Scenario | B1: Benefits | 2.0% | C1: Costs | 2.0% | D1: Benefits/Costs | 2.0% | E1: Benefits-Costs | 2.0% | F1: Benefits | 12.0% | G1: Costs | 12.0% | H1: Benefits/Costs | 12.0% | I1: Benefits-Costs | 12.0% | J1: Benefits | 20.0% | K1: Costs | 20.0% | L1: Benefits/Costs | 20.0% | M1: Benefits-Costs | 20.0% | N1: Units
A2: 45Q-2040 | B2: -87041.624 | C2: 68266.071 | D2: -1.2750349 | E2: -18775.553 | F2: -24009.774 | G2: 29691.982 | H2: -0.80862821 | I2: 5682.208 | J2: -10209.74 | K2: 18095.102 | L2: -0.56422673 | M2: 7885.3619 | N2: Million $USD or unitless
A3: 45Q-2050 | B3: -277189.41 | C3: 285224.81 | D3: -0.97182786 | E3: 8035.3927 | F3: -48914.657 | G3: 59208.422 | H3: -0.82614357 | I3: 10293.765 | J3: -15980.398 | K3: 25187.002 | L3: -0.63447005 | M3: 9206.6034 | N3: Million $USD or unitless
A4: CDRIA-2035 | B4: -52712.757 | C4: 73875.667 | D4: -0.71353341 | E4: 21162.91 | F4: -18634.107 | G4: 40963.228 | H4: -0.45489841 | I4: 22329.12 | J4: -10131.117 | K4: 27756.054 | L4: -0.36500567 | M4: 17624.937 | N4: Million $USD or unitless
A5: CDRIA-2050 | B5: -568357.47 | C5: 643393.82 | D5: -0.88337416 | E5: 75036.345 | F5: -107357.14 | G5: 133387.42 | H5: -0.80485203 | I5: 26030.284 | J5: -37918.656 | K5: 54270.809 | L5: -0.69869339 | M5: 16352.154 | N5: Million $USD or unitless
A6: Innovation-DACHubs | B6: -629.11242 | C6: 17177.259 | D6: -0.036624726 | E6: 16548.147 | F6: -412.48126 | G6: 13602.397 | H6: -0.030324161 | I6: 13189.915 | J6: -335.61574 | K6: 11630.812 | L6: -0.028855746 | M6: 11295.196 | N6: Million $USD or unitless
A7: Innovation-maintain | B7: -24187.679 | C7: 15388.102 | D7: -1.5718429 | E7: -8799.5768 | F7: -5025.3694 | G7: 11163.603 | H7: -0.45015659 | I7: 6138.2334 | J7: -2036.7477 | K7: 9267.5678 | L7: -0.21977155 | M7: 7230.8201 | N7: Million $USD or unitless
A8: Innovation-rhodium18b | B8: -58217.953 | C8: 27759.151 | D8: -2.0972527 | E8: -30458.802 | F8: -12921.436 | G8: 16483.501 | H8: -0.78390115 | I8: 3562.0657 | J8: -5363.8814 | K8: 12128.472 | L8: -0.44225532 | M8: 6764.591 | N8: Million $USD or unitless
A9: Innovation-rhodium6b | B9: -36532.336 | C9: 17910.879 | D9: -2.039673 | E9: -18621.457 | F9: -8027.2493 | G9: 12253.33 | H9: -0.65510759 | I9: 4226.0804 | J9: -3292.7797 | K9: 9764.4966 | L9: -0.3372196 | M9: 6471.7169 | N9: Million $USD or unitless
A10: Innovation-triple | B10: -43040.12 | C10: 20122.442 | D10: -2.1389114 | E10: -22917.678 | F10: -9350.1536 | G10: 13167.048 | H10: -0.7101177 | I10: 3816.8941 | J10: -3948.2113 | K10: 10601.574 | L10: -0.37241745 | M10: 6653.3632 | N10: Million $USD or unitless
A11: 500 Mt Baseline | B11: 0 | C11: 13051.018 | D11: 0 | E11: 13051.018 | F11: 0 | G11: 10184.316 | H11: 0 | I11: 10184.316 | J11: 0 | K11: 8618.8843 | L11: 0 | M11: 8618.8843 | N11: Million $USD or unitless
A12: Procure3B | B12: -38255.646 | C12: 40895.334 | D12: -0.93545258 | E12: 2639.6883 | F12: -10717.544 | G12: 26505.399 | H12: -0.40435323 | I12: 15787.856 | J12: -5715.8743 | K12: 20036.443 | L12: -0.28527389 | M12: 14320.569 | N12: Million $USD or unitless
A13: ProcureRhodium | B13: -118894.25 | C13: 1189299.4 | D13: -0.099969989 | E13: 1070405.1 | F13: -43687.747 | G13: 307571.13 | H13: -0.14204112 | I13: 263883.38 | J13: -25574.065 | K13: 147554.19 | L13: -0.17331981 | M13: 121980.13 | N13: Million $USD or unitless
... A15: Optimal | B15: -110898.5 | C15: 70029.473 | D15: -1.5835975 | E15: -40869.023 | F15: -29063.628 | G15: 30483.986 | H15: -0.95340644 | I15: 1420.3575 | J15: -12270.083 | K15: 18658.255 | L15: -0.65762221 | M15: 6388.1722 | N15: Million $USD or unitless
A17: Marginal | B17: Benefits | 2.0% | C17: Costs | 2.0% | D17: Benefits/Costs | 2.0% | E17: Benefits-Costs | 2.0% | F17: Benefits | 12.0% | G17: Costs | 12.0% | H17: Benefits/Costs | 12.0% | I17: Benefits-Costs | 12.0% | J17: Benefits | 20.0% | K17: Costs | 20.0% | L17: Benefits/Costs | 20.0% | M17: Benefits-Costs | 20.0% | N17: Units
A18: 45Q-2040 | B18: =B2-B$33 -> -87041.624 | C18: =C2-C$33 -> 55215.053 | D18: =B18/C18 -> -1.5764111 | E18: =B18+C18 -> -31826.571 | F18: =F2-F$33 -> -24009.774 | G18: =G2-G$33 -> 19507.667 | H18: =F18/G18 -> -1.2307866 | I18: =F18+G18 -> -4502.1078 | J18: =J2-J$33 -> -10209.74 | K18: =K2-K$33 -> 9476.218 | L18: =J18/K18 -> -1.0774067 | M18: =J18+K18 -> -733.52238 | N18: Million $USD or unitless
A19: 45Q-2050 | B19: =B3-B$33 -> -277189.41 | C19: =C3-C$33 -> 272173.79 | D19: =B19/C19 -> -1.018428 | E19: =B19+C19 -> -5015.625 | F19: =F3-F$33 -> -48914.657 | G19: =G3-G$33 -> 49024.106 | H19: =F19/G19 -> -0.99776744 | I19: =F19+G19 -> 109.44915 | J19: =J3-J$33 -> -15980.398 | K19: =K3-K$33 -> 16568.117 | L19: =J19/K19 -> -0.9645271 | M19: =J19+K19 -> 587.71912 | N19: Million $USD or unitless
A20: CDRIA-2035 | B20: =B4-B$33 -> -52712.757 | C20: =C4-C$33 -> 60824.649 | D20: =B20/C20 -> -0.86663479 | E20: =B20+C20 -> 8111.8924 | F20: =F4-F$33 -> -18634.107 | G20: =G4-G$33 -> 30778.912 | H20: =F20/G20 -> -0.605418 | I20: =F20+G20 -> 12144.805 | J20: =J4-J$33 -> -10131.117 | K20: =K4-K$33 -> 19137.17 | L20: =J20/K20 -> -0.52939474 | M20: =J20+K20 -> 9006.0528 | N20: Million $USD or unitless
A21: CDRIA-2050 | B21: =B5-B$33 -> -568357.47 | C21: =C5-C$33 -> 630342.8 | D21: =B21/C21 -> -0.9016641 | E21: =B21+C21 -> 61985.327 | F21: =F5-F$33 -> -107357.14 | G21: =G5-G$33 -> 123203.1 | H21: =F21/G21 -> -0.87138337 | I21: =F21+G21 -> 15845.969 | J21: =J5-J$33 -> -37918.656 | K21: =K5-K$33 -> 45651.925 | L21: =J21/K21 -> -0.83060365 | M21: =J21+K21 -> 7733.2692 | N21: Million $USD or unitless
A22: Innovation-DACHubs | B22: =B6-B$33 -> -629.11242 | C22: =C6-C$33 -> 4126.2416 | D22: =B22/C22 -> -0.15246621 | E22: =B22+C22 -> 3497.1291 | F22: =F6-F$33 -> -412.48126 | G22: =G6-G$33 -> 3418.0808 | H22: =F22/G22 -> -0.12067628 | I22: =F22+G22 -> 3005.5995 | J22: =J6-J$33 -> -335.61574 | K22: =K6-K$33 -> 3011.9272 | L22: =J22/K22 -> -0.1114289 | M22: =J22+K22 -> 2676.3115 | N22: Million $USD or unitless
A23: Innovation-maintain | B23: =B7-B$33 -> -24187.679 | C23: =C7-C$33 -> 2337.0841 | D23: =B23/C23 -> -10.349512 | E23: =B23+C23 -> -21850.594 | F23: =F7-F$33 -> -5025.3694 | G23: =G7-G$33 -> 979.28707 | H23: =F23/G23 -> -5.1316611 | I23: =F23+G23 -> -4046.0823 | J23: =J7-J$33 -> -2036.7477 | K23: =K7-K$33 -> 648.68348 | L23: =J23/K23 -> -3.1398175 | M23: =J23+K23 -> -1388.0642 | N23: Million $USD or unitless
A24: Innovation-rhodium18b | B24: =B8-B$33 -> -58217.953 | C24: =C8-C$33 -> 14708.133 | D24: =B24/C24 -> -3.9582151 | E24: =B24+C24 -> -43509.82 | F24: =F8-F$33 -> -12921.436 | G24: =G8-G$33 -> 6299.1856 | H24: =F24/G24 -> -2.0512867 | I24: =F24+G24 -> -6622.25 | J24: =J8-J$33 -> -5363.8814 | K24: =K8-K$33 -> 3509.5881 | L24: =J24/K24 -> -1.5283507 | M24: =J24+K24 -> -1854.2933 | N24: Million $USD or unitless
A25: Innovation-rhodium6b | B25: =B9-B$33 -> -36532.336 | C25: =C9-C$33 -> 4859.861 | D25: =B25/C25 -> -7.5171565 | E25: =B25+C25 -> -31672.475 | F25: =F9-F$33 -> -8027.2493 | G25: =G9-G$33 -> 2069.014 | H25: =F25/G25 -> -3.8797462 | I25: =F25+G25 -> -5958.2353 | J25: =J9-J$33 -> -3292.7797 | K25: =K9-K$33 -> 1145.6123 | L25: =J25/K25 -> -2.8742531 | M25: =J25+K25 -> -2147.1674 | N25: Million $USD or unitless
A26: Innovation-triple | B26: =B10-B$33 -> -43040.12 | C26: =C10-C$33 -> 7071.4241 | D26: =B26/C26 -> -6.0864855 | E26: =B26+C26 -> -35968.696 | F26: =F10-F$33 -> -9350.1536 | G26: =G10-G$33 -> 2982.7319 | H26: =F26/G26 -> -3.1347616 | I26: =F26+G26 -> -6367.4217 | J26: =J10-J$33 -> -3948.2113 | K26: =K10-K$33 -> 1982.6901 | L26: =J26/K26 -> -1.9913406 | M26: =J26+K26 -> -1965.5212 | N26: Million $USD or unitless
A27: Procure3B | B27: =B12-B$33 -> -38255.646 | C27: =C12-C$33 -> 27844.317 | D27: =B27/C27 -> -1.3739122 | E27: =B27+C27 -> -10411.329 | F27: =F12-F$33 -> -10717.544 | G27: =G12-G$33 -> 16321.084 | H27: =F27/G27 -> -0.65666864 | I27: =F27+G27 -> 5603.5399 | J27: =J12-J$33 -> -5715.8743 | K27: =K12-K$33 -> 11417.559 | L27: =J27/K27 -> -0.50062139 | M27: =J27+K27 -> 5701.6849 | N27: Million $USD or unitless
A28: ProcureRhodium | B28: =B13-B$33 -> -118894.25 | C28: =C13-C$33 -> 1176248.4 | D28: =B28/C28 -> -0.1010792 | E28: =B28+C28 -> 1057354.1 | F28: =F13-F$33 -> -43687.747 | G28: =G13-G$33 -> 297386.81 | H28: =F28/G28 -> -0.14690546 | I28: =F28+G28 -> 253699.06 | J28: =J13-J$33 -> -25574.065 | K28: =K13-K$33 -> 138935.31 | L28: =J28/K28 -> -0.18407175 | M28: =J28+K28 -> 113361.24 | N28: Million $USD or unitless
A29: ProcureScaling | B29: =B14-B$33 -> -27847.775 | C29: =C14-C$33 -> 11354.46 | D29: =B29/C29 -> -2.4525847 | E29: =B29+C29 -> -16493.315 | F29: =F14-F$33 -> -6640.4508 | G29: =G14-G$33 -> 6356.3922 | H29: =F29/G29 -> -1.0446886 | I29: =F29+G29 -> -284.05857 | J29: =J14-J$33 -> -3093.7558 | K29: =K14-K$33 -> 4312.2304 | L29: =J29/K29 -> -0.7174375 | M29: =J29+K29 -> 1218.4746 | N29: Million $USD or unitless
A30: Optimal | B30: =B15-B$33 -> -110898.5 | C30: =C15-C$33 -> 56978.456 | D30: =B30/C30 -> -1.9463233 | E30: =B30+C30 -> -53920.041 | F30: =F15-F$33 -> -29063.628 | G30: =G15-G$33 -> 20299.67 | H30: =F30/G30 -> -1.4317291 | I30: =F30+G30 -> -8763.9582 | J30: =J15-J$33 -> -12270.083 | K30: =K15-K$33 -> 10039.371 | L30: =J30/K30 -> -1.2221964 | M30: =J30+K30 -> -2230.7122 | N30: Million $USD or unitless
A32: Low Baseline | B32: 2% Benefits | C32: 2% Costs | F32: 12% Benefits | G32: 12% Costs | J32: 20% Benefits | K32: 20% Costs
B33: 0 | C33: 13051.018 | D33: 0 | E33: 13051.018 | F33: 0 | G33: 10184.316 | H33: 0 | I33: 10184.316 | J33: 0 | K33: 8618.8843 | L33: 0 | M33: 8618.8843

Sheet High
A1: Scenario | B1: Benefits | 2.0% | C1: Costs | 2.0% | D1: Benefits/Costs | 2.0% | E1: Benefits-Costs | 2.0% | F1: Benefits | 12.0% | G1: Costs | 12.0% | H1: Benefits/Costs | 12.0% | I1: Benefits-Costs | 12.0% | J1: Benefits | 20.0% | K1: Costs | 20.0% | L1: Benefits/Costs | 20.0% | M1: Benefits-Costs | 20.0% | N1: Units
A2: 45Q-2040 | B2: -169783.38 | C2: 109571.66 | D2: -1.5495191 | E2: -60211.721 | F2: -44358.724 | G2: 44038.543 | H2: -1.0072705 | I2: -320.18113 | J2: -18237.935 | K2: 25144.881 | L2: -0.72531402 | M2: 6906.9464 | N2: Million $USD or unitless
A3: 45Q-2050 | B3: -754774.03 | C3: 764266.28 | D3: -0.98757992 | E3: 9492.2506 | F3: -118636.45 | G3: 130113.04 | H3: -0.91179522 | I3: 11476.593 | J3: -35032.953 | K3: 45257.658 | L3: -0.77407791 | M3: 10224.705 | N3: Million $USD or unitless
A4: CDRIA-2035 | B4: -85029.801 | C4: 102198.08 | D4: -0.83200976 | E4: 17168.28 | F4: -26414.789 | G4: 55367.134 | H4: -0.47708427 | I4: 28952.345 | J4: -13669.171 | K4: 36771.161 | L4: -0.37173617 | M4: 23101.99 | N4: Million $USD or unitless
A5: CDRIA-2050 | B5: -1464989.8 | C5: 1485429.4 | D5: -0.98623993 | E5: 20439.607 | F5: -244021.11 | G5: 269761.84 | H5: -0.90457979 | I5: 25740.731 | J5: -77084.451 | K5: 96376.642 | L5: -0.79982503 | M5: 19292.192 | N5: Million $USD or unitless
A6: 1500 Mt Baseline | B6: 0 | C6: 15116.458 | D6: 0 | E6: 15116.458 | F6: 0 | G6: 11664.787 | H6: 0 | I6: 11664.787 | J6: 0 | K6: 9787.7638 | L6: 0 | M6: 9787.7638 | N6: Million $USD or unitless
A7: Innovation-DACHubs | B7: -3727.1948 | C7: 19326.595 | D7: -0.19285315 | E7: 15599.4 | F7: -879.19316 | G7: 15143.006 | H7: -0.058059356 | I7: 14263.812 | J7: -494.59746 | K7: 12847.173 | L7: -0.038498543 | M7: 12352.576 | N7: Million $USD or unitless
A8: Innovation-maintain | B8: -45921.598 | C8: 17442.37 | D8: -2.6327613 | E8: -28479.227 | F8: -8674.7509 | G8: 12636.066 | H8: -0.68650724 | I8: 3961.3153 | J8: -3198.9575 | K8: 10430.124 | L8: -0.30670367 | M8: 7231.1669 | N8: Million $USD or unitless
A9: Innovation-rhodium18b | B9: -107072.64 | C9: 29750.175 | D9: -3.599059 | E9: -77322.461 | F9: -21894.339 | G9: 17910.632 | H9: -1.2224214 | I9: -3983.707 | J9: -8514.5423 | K9: 13255.237 | L9: -0.64235308 | M9: 4740.6947 | N9: Million $USD or unitless
A10: Innovation-rhodium6b | B10: -69242.862 | C10: 19942.878 | D10: -3.4720597 | E10: -49299.984 | F10: -13872.358 | G10: 13709.832 | H10: -1.0118547 | I10: -162.52596 | J10: -5283.9158 | K10: 10914.452 | L10: -0.48412106 | M10: 5630.5358 | N10: Million $USD or unitless
A11: Innovation-triple | B11: -81117.731 | C11: 22161.367 | D11: -3.6603216 | E11: -58956.364 | F11: -15910.769 | G11: 14628.514 | H11: -1.0876545 | I11: -1282.2548 | J11: -6110.8874 | K11: 11755.449 | L11: -0.51983447 | M11: 5644.5613 | N11: Million $USD or unitless
A12: Procure3B | B12: -70006.101 | C12: 43027.701 | D12: -1.6270007 | E12: -26978.4 | F12: -16549.279 | G12: 28014.328 | H12: -0.59074337 | I12: 11465.05 | J12: -7773.979 | K12: 21219.906 | L12: -0.36635313 | M12: 13445.927 | N12: Million $USD or unitless
A13: ProcureRhodium | B13: -185026.91 | C13: 1222255.1 | D13: -0.15138158 | E13: 1037228.2 | F13: -50271.577 | G13: 314637.33 | H13: -0.15977626 | I13: 264365.76 | J13: -26217.888 | K13: 150342.9 | L13: -0.17438727 | M13: 124125.01 | N13: Million $USD or unitless
... A15: Optimal | B15: -107282.41 | C15: 29019.632 | D15: -3.6968906 | E15: -78262.774 | F15: -20872.628 | G15: 19127.911 | H15: -1.0912132 | I15: -1744.7171 | J15: -8174.0891 | K15: 14840.022 | L15: -0.55081381 | M15: 6665.933 | N15: Million $USD or unitless
A17: Marginal | B17: Benefits | 2.0% | C17: Costs | 2.0% | D17: Benefits/Costs | 2.0% | E17: Benefits-Costs | 2.0% | F17: Benefits | 12.0% | G17: Costs | 12.0% | H17: Benefits/Costs | 12.0% | I17: Benefits-Costs | 12.0% | J17: Benefits | 20.0% | K17: Costs | 20.0% | L17: Benefits/Costs | 20.0% | M17: Benefits-Costs | 20.0% | N17: Units
A18: 45Q-2040 | B18: =B2-B$33 -> -169783.38 | C18: =C2-C$33 -> 94455.206 | D18: =B18/C18 -> -1.7975016 | E18: =B18+C18 -> -75328.178 | F18: =F2-F$33 -> -44358.724 | G18: =G2-G$33 -> 32373.756 | H18: =F18/G18 -> -1.3702063 | I18: =F18+G18 -> -11984.968 | J18: =J2-J$33 -> -18237.935 | K18: =K2-K$33 -> 15357.117 | L18: =J18/K18 -> -1.1875884 | M18: =J18+K18 -> -2880.8174 | N18: Million $USD or unitless
A19: 45Q-2050 | B19: =B3-B$33 -> -754774.03 | C19: =C3-C$33 -> 749149.82 | D19: =B19/C19 -> -1.0075075 | E19: =B19+C19 -> -5624.2071 | F19: =F3-F$33 -> -118636.45 | G19: =G3-G$33 -> 118448.26 | H19: =F19/G19 -> -1.0015888 | I19: =F19+G19 -> -188.19435 | J19: =J3-J$33 -> -35032.953 | K19: =K3-K$33 -> 35469.895 | L19: =J19/K19 -> -0.98768135 | M19: =J19+K19 -> 436.94107 | N19: Million $USD or unitless
A20: CDRIA-2035 | B20: =B4-B$33 -> -85029.801 | C20: =C4-C$33 -> 87081.624 | D20: =B20/C20 -> -0.97643794 | E20: =B20+C20 -> 2051.8224 | F20: =F4-F$33 -> -26414.789 | G20: =G4-G$33 -> 43702.347 | H20: =F20/G20 -> -0.60442495 | I20: =F20+G20 -> 17287.558 | J20: =J4-J$33 -> -13669.171 | K20: =K4-K$33 -> 26983.397 | L20: =J20/K20 -> -0.50657708 | M20: =J20+K20 -> 13314.226 | N20: Million $USD or unitless
A21: CDRIA-2050 | B21: =B5-B$33 -> -1464989.8 | C21: =C5-C$33 -> 1470312.9 | D21: =B21/C21 -> -0.99637958 | E21: =B21+C21 -> 5323.1489 | F21: =F5-F$33 -> -244021.11 | G21: =G5-G$33 -> 258097.05 | H21: =F21/G21 -> -0.94546259 | I21: =F21+G21 -> 14075.944 | J21: =J5-J$33 -> -77084.451 | K21: =K5-K$33 -> 86588.879 | L21: =J21/K21 -> -0.89023501 | M21: =J21+K21 -> 9504.4277 | N21: Million $USD or unitless
A22: Innovation-DACHubs | B22: =B7-B$33 -> -3727.1948 | C22: =C7-C$33 -> 4210.1376 | D22: =B22/C22 -> -0.88529049 | E22: =B22+C22 -> 482.9428 | F22: =F7-F$33 -> -879.19316 | G22: =G7-G$33 -> 3478.2184 | H22: =F22/G22 -> -0.25277112 | I22: =F22+G22 -> 2599.0253 | J22: =J7-J$33 -> -494.59746 | K22: =K7-K$33 -> 3059.4095 | L22: =J22/K22 -> -0.16166435 | M22: =J22+K22 -> 2564.8121 | N22: Million $USD or unitless
A23: Innovation-maintain | B23: =B8-B$33 -> -45921.598 | C23: =C8-C$33 -> 2325.9124 | D23: =B23/C23 -> -19.743477 | E23: =B23+C23 -> -43595.685 | F23: =F8-F$33 -> -8674.7509 | G23: =G8-G$33 -> 971.27899 | H23: =F23/G23 -> -8.9312659 | I23: =F23+G23 -> -7703.472 | J23: =J8-J$33 -> -3198.9575 | K23: =K8-K$33 -> 642.36055 | L23: =J23/K23 -> -4.9800029 | M23: =J23+K23 -> -2556.5969 | N23: Million $USD or unitless
A24: Innovation-rhodium18b | B24: =B9-B$33 -> -107072.64 | C24: =C9-C$33 -> 14633.718 | D24: =B24/C24 -> -7.3168445 | E24: =B24+C24 -> -92438.919 | F24: =F9-F$33 -> -21894.339 | G24: =G9-G$33 -> 6245.845 | H24: =F24/G24 -> -3.5054247 | I24: =F24+G24 -> -15648.494 | J24: =J9-J$33 -> -8514.5423 | K24: =K9-K$33 -> 3467.4732 | L24: =J24/K24 -> -2.4555466 | M24: =J24+K24 -> -5047.0691 | N24: Million $USD or unitless
A25: Innovation-rhodium6b | B25: =B10-B$33 -> -69242.862 | C25: =C10-C$33 -> 4826.4201 | D25: =B25/C25 -> -14.34663 | E25: =B25+C25 -> -64416.442 | F25: =F10-F$33 -> -13872.358 | G25: =G10-G$33 -> 2045.0445 | H25: =F25/G25 -> -6.7834015 | I25: =F25+G25 -> -11827.313 | J25: =J10-J$33 -> -5283.9158 | K25: =K10-K$33 -> 1126.6878 | L25: =J25/K25 -> -4.689778 | M25: =J25+K25 -> -4157.228 | N25: Million $USD or unitless
A26: Innovation-triple | B26: =B11-B$33 -> -81117.731 | C26: =C11-C$33 -> 7044.9095 | D26: =B26/C26 -> -11.514375 | E26: =B26+C26 -> -74072.822 | F26: =F11-F$33 -> -15910.769 | G26: =G11-G$33 -> 2963.7267 | H26: =F26/G26 -> -5.3685006 | I26: =F26+G26 -> -12947.042 | J26: =J11-J$33 -> -6110.8874 | K26: =K11-K$33 -> 1967.6849 | L26: =J26/K26 -> -3.105623 | M26: =J26+K26 -> -4143.2025 | N26: Million $USD or unitless
A27: Procure3B | B27: =B12-B$33 -> -70006.101 | C27: =C12-C$33 -> 27911.243 | D27: =B27/C27 -> -2.5081685 | E27: =B27+C27 -> -42094.858 | F27: =F12-F$33 -> -16549.279 | G27: =G12-G$33 -> 16349.541 | H27: =F27/G27 -> -1.0122167 | I27: =F27+G27 -> -199.73757 | J27: =J12-J$33 -> -7773.979 | K27: =K12-K$33 -> 11432.143 | L27: =J27/K27 -> -0.68001067 | M27: =J27+K27 -> 3658.1636 | N27: Million $USD or unitless
A28: ProcureRhodium | B28: =B13-B$33 -> -185026.91 | C28: =C13-C$33 -> 1207138.6 | D28: =B28/C28 -> -0.15327727 | E28: =B28+C28 -> 1022111.7 | F28: =F13-F$33 -> -50271.577 | G28: =G13-G$33 -> 302972.55 | H28: =F28/G28 -> -0.16592783 | I28: =F28+G28 -> 252700.97 | J28: =J13-J$33 -> -26217.888 | K28: =K13-K$33 -> 140555.14 | L28: =J28/K28 -> -0.18653098 | M28: =J28+K28 -> 114337.25 | N28: Million $USD or unitless
A29: ProcureScaling | B29: =B14-B$33 -> -52677.847 | C29: =C14-C$33 -> 11419.991 | D29: =B29/C29 -> -4.6127746 | E29: =B29+C29 -> -41257.855 | F29: =F14-F$33 -> -11192.743 | G29: =G14-G$33 -> 6387.5268 | H29: =F29/G29 -> -1.7522812 | I29: =F29+G29 -> -4805.2163 | J29: =J14-J$33 -> -4681.5643 | K29: =K14-K$33 -> 4330.4416 | L29: =J29/K29 -> -1.0810824 | M29: =J29+K29 -> -351.12275 | N29: Million $USD or unitless
A30: Optimal | B30: =B15-B$33 -> -107282.41 | C30: =C15-C$33 -> 13903.174 | D30: =B30/C30 -> -7.7163966 | E30: =B30+C30 -> -93379.231 | F30: =F15-F$33 -> -20872.628 | G30: =G15-G$33 -> 7463.1233 | H30: =F30/G30 -> -2.7967684 | I30: =F30+G30 -> -13409.504 | J30: =J15-J$33 -> -8174.0891 | K30: =K15-K$33 -> 5052.2583 | L30: =J30/K30 -> -1.617908 | M30: =J30+K30 -> -3121.8308 | N30: Million $USD or unitless
A32: Low Baseline | B32: 2% Benefits | C32: 2% Costs | F32: 12% Benefits | G32: 12% Costs | J32: 20% Benefits | K32: 20% Costs
B33: 0 | C33: 15116.458 | D33: 0 | E33: 15116.458 | F33: 0 | G33: 11664.787 | H33: 0 | I33: 11664.787 | J33: 0 | K33: 9787.7638 | L33: 0 | M33: 9787.7638

Sheet Plotting Marginal CostsBenefits
A1: =Low!A1 -> Scenario | B1: Baseline | C1: Benefits | 12.0% | D1: Costs | 12.0% | E1: Innovation - 500 Mt | F1: Subsidy - 500 Mt | G1: Procurement - 500 Mt | H1: Optimal - 500 Mt | I1: Innovation - 1.5 Gt | J1: Subsidy - 1.5 Gt | K1: Procurement - 1.5 Gt | L1: Optimal - 1.5 Gt | N1: 0.12 | O1: Benefits have sign changed compared to Supplementary Tables 19-30
A2: =Low!A18 -> 45Q-2040 | B2: 500 Mt | C2: =-Low!F18/1000 -> 24.009774 | D2: =Low!G18/1000 -> 19.507667 | F2: =C2 -> 24.009774
A3: =Low!A19 -> 45Q-2050 | B3: 500 Mt | C3: =-Low!F19/1000 -> 48.914657 | D3: =Low!G19/1000 -> 49.024106 | F3: =C3 -> 48.914657
A4: =Low!A20 -> CDRIA-2035 | B4: 500 Mt | C4: =-Low!F20/1000 -> 18.634107 | D4: =Low!G20/1000 -> 30.778912 | F4: =C4 -> 18.634107
A5: =Low!A21 -> CDRIA-2050 | B5: 500 Mt | C5: =-Low!F21/1000 -> 107.35714 | D5: =Low!G21/1000 -> 123.2031 | F5: =C5 -> 107.35714
A6: =Low!A22 -> Innovation-DACHubs | B6: 500 Mt | C6: =-Low!F22/1000 -> 0.41248126 | D6: =Low!G22/1000 -> 3.4180808 | E6: =C6 -> 0.41248126
A7: =Low!A23 -> Innovation-maintain | B7: 500 Mt | C7: =-Low!F23/1000 -> 5.0253694 | D7: =Low!G23/1000 -> 0.97928707 | E7: =C7 -> 5.0253694
A8: =Low!A24 -> Innovation-rhodium18b | B8: 500 Mt | C8: =-Low!F24/1000 -> 12.921436 | D8: =Low!G24/1000 -> 6.2991856 | E8: =C8 -> 12.921436
A9: =Low!A25 -> Innovation-rhodium6b | B9: 500 Mt | C9: =-Low!F25/1000 -> 8.0272493 | D9: =Low!G25/1000 -> 2.069014 | E9: =C9 -> 8.0272493
A10: =Low!A26 -> Innovation-triple | B10: 500 Mt | C10: =-Low!F26/1000 -> 9.3501536 | D10: =Low!G26/1000 -> 2.9827319 | E10: =C10 -> 9.3501536
A11: =Low!A27 -> Procure3B | B11: 500 Mt | C11: =-Low!F27/1000 -> 10.717544 | D11: =Low!G27/1000 -> 16.321084 | G11: =C11 -> 10.717544
A12: =Low!A28 -> ProcureRhodium | B12: 500 Mt | C12: =-Low!F28/1000 -> 43.687747 | D12: =Low!G28/1000 -> 297.38681 | G12: =C12 -> 43.687747
A13: =Low!A29 -> ProcureScaling | B13: 500 Mt | C13: =-Low!F29/1000 -> 6.6404508 | D13: =Low!G29/1000 -> 6.3563922 | G13: =C13 -> 6.6404508
A14: =Low!A30 -> Optimal | B14: 500 Mt | C14: =-Low!F30/1000 -> 29.063628 | D14: =Low!G30/1000 -> 20.29967 | H14: =C14 -> 29.063628
A15: =High!A18 -> 45Q-2040 | B15: 1.5 Gt | C15: =-High!F18/1000 -> 44.358724 | D15: =High!G18/1000 -> 32.373756 | J15: =C15 -> 44.358724
A16: =High!A19 -> 45Q-2050 | B16: 1.5 Gt | C16: =-High!F19/1000 -> 118.63645 | D16: =High!G19/1000 -> 118.44826 | J16: =C16 -> 118.63645
A17: =High!A20 -> CDRIA-2035 | B17: 1.5 Gt | C17: =-High!F20/1000 -> 26.414789 | D17: =High!G20/1000 -> 43.702347 | J17: =C17 -> 26.414789
A18: =High!A21 -> CDRIA-2050 | B18: 1.5 Gt | C18: =-High!F21/1000 -> 244.02111 | D18: =High!G21/1000 -> 258.09705 | J18: =C18 -> 244.02111
A19: =High!A22 -> Innovation-DACHubs | B19: 1.5 Gt | C19: =-High!F22/1000 -> 0.87919316 | D19: =High!G22/1000 -> 3.4782184 | I19: =C19 -> 0.87919316
A20: =High!A23 -> Innovation-maintain | B20: 1.5 Gt | C20: =-High!F23/1000 -> 8.6747509 | D20: =High!G23/1000 -> 0.97127899 | I20: =C20 -> 8.6747509
A21: =High!A24 -> Innovation-rhodium18b | B21: 1.5 Gt | C21: =-High!F24/1000 -> 21.894339 | D21: =High!G24/1000 -> 6.245845 | I21: =C21 -> 21.894339
A22: =High!A25 -> Innovation-rhodium6b | B22: 1.5 Gt | C22: =-High!F25/1000 -> 13.872358 | D22: =High!G25/1000 -> 2.0450445 | I22: =C22 -> 13.872358
A23: =High!A26 -> Innovation-triple | B23: 1.5 Gt | C23: =-High!F26/1000 -> 15.910769 | D23: =High!G26/1000 -> 2.9637267 | I23: =C23 -> 15.910769
A24: =High!A27 -> Procure3B | B24: 1.5 Gt | C24: =-High!F27/1000 -> 16.549279 | D24: =High!G27/1000 -> 16.349541 | K24: =C24 -> 16.549279
A25: =High!A28 -> ProcureRhodium | B25: 1.5 Gt | C25: =-High!F28/1000 -> 50.271577 | D25: =High!G28/1000 -> 302.97255 | K25: =C25 -> 50.271577
A26: =High!A29 -> ProcureScaling | B26: 1.5 Gt | C26: =-High!F29/1000 -> 11.192743 | D26: =High!G29/1000 -> 6.3875268 | K26: =C26 -> 11.192743
A27: =High!A30 -> Optimal | B27: 1.5 Gt | C27: =-High!F30/1000 -> 20.872628 | D27: =High!G30/1000 -> 7.4631233 | L27: =C27 -> 20.872628
C30: Negative Benefits are Bad
A31: =Low!A32 -> Low Baseline | B31: Baseline | C31: Benefits | 2.0% | D31: Costs | 2.0% | E31: Innovation - 500 Mt | F31: Subsidy - 500 Mt | G31: Procurement - 500 Mt | H31: Optimal - 500 Mt | I31: Innovation - 1.5 Gt | J31: Subsidy - 1.5 Gt | K31: Procurement - 1.5 Gt | L31: Optimal - 1.5 Gt | N31: 0.02
A32: =A2 -> 45Q-2040 | B32: 500 Mt | C32: =-Low!B18/1000 -> 87.041624 | D32: =Low!C18/1000 -> 55.215053 | F32: =C32 -> 87.041624
A33: =A3 -> 45Q-2050 | B33: 500 Mt | C33: =-Low!B19/1000 -> 277.18941 | D33: =Low!C19/1000 -> 272.17379 | F33: =C33 -> 277.18941
A34: =A4 -> CDRIA-2035 | B34: 500 Mt | C34: =-Low!B20/1000 -> 52.712757 | D34: =Low!C20/1000 -> 60.824649 | F34: =C34 -> 52.712757
A35: =A5 -> CDRIA-2050 | B35: 500 Mt | C35: =-Low!B21/1000 -> 568.35747 | D35: =Low!C21/1000 -> 630.3428 | F35: =C35 -> 568.35747
A36: =A6 -> Innovation-DACHubs | B36: 500 Mt | C36: =-Low!B22/1000 -> 0.62911242 | D36: =Low!C22/1000 -> 4.1262416 | E36: =C36 -> 0.62911242
A37: =A7 -> Innovation-maintain | B37: 500 Mt | C37: =-Low!B23/1000 -> 24.187679 | D37: =Low!C23/1000 -> 2.3370841 | E37: =C37 -> 24.187679
A38: =A8 -> Innovation-rhodium18b | B38: 500 Mt | C38: =-Low!B24/1000 -> 58.217953 | D38: =Low!C24/1000 -> 14.708133 | E38: =C38 -> 58.217953
A39: =A9 -> Innovation-rhodium6b | B39: 500 Mt | C39: =-Low!B25/1000 -> 36.532336 | D39: =Low!C25/1000 -> 4.859861 | E39: =C39 -> 36.532336
A40: =A10 -> Innovation-triple | B40: 500 Mt | C40: =-Low!B26/1000 -> 43.04012 | D40: =Low!C26/1000 -> 7.0714241 | E40: =C40 -> 43.04012
A41: =A11 -> Procure3B | B41: 500 Mt | C41: =-Low!B27/1000 -> 38.255646 | D41: =Low!C27/1000 -> 27.844317 | G41: =C41 -> 38.255646
A42: =A12 -> ProcureRhodium | B42: 500 Mt | C42: =-Low!B28/1000 -> 118.89425 | D42: =Low!C28/1000 -> 1176.2484 | G42: =C42 -> 118.89425
...

Sheet Marginal C emissions
A1: Scenario | B1: CDR (Mt) | C1: C emissions (Mt C) | D1: C emission (Mt CO2-eq) | E1: Additionality of CDR | I1: From CO2-CDR Social Costs .csv
A2: Low Baseline | B2: 500 | C2: =C19 -> 40.97 | D2: =D19 -> 150.22333 | E2: N/A
A3: High Baseline | B3: 1500 | C3: =C21 -> 263.8 | D3: =D21 -> 967.26667 | E3: =1-(D3-D2)/(B3-B2) -> 0.18295667
A5: 2040
A6: Scenario | B6: CDR (Mt) | C6: C emissions (Mt C) | D6: C emission (Mt CO2-eq) | E6: Effectiveness of CDR
A7: 100 Mt baseline | B7: 44.88 | C7: 696.53 | D7: =C7*44/12 -> 2553.9433 | E7: N/A
A8: 500 Mt baseline | B8: 117.9 | C8: 706.24 | D8: =C8*44/12 -> 2589.5467 | E8: =1-(D8-D7)/(B8-B7) -> 0.51241669
A9: 1500 Mt baseline | B9: 227.92 | C9: 721.47 | D9: =C9*44/12 -> 2645.39 | E9: =1-(D9-D8)/(B9-B8) -> 0.49242562
A10: 2400 Mt baseline | B10: 302.17 | C10: 736.34 | D10: =C10*44/12 -> 2699.9133 | E10: =1-(D10-D9)/(B10-B9) -> 0.26567901
A11: 4100 Mt baseline | B11: 416.68 | C11: 754.71 | D11: =C11*44/12 -> 2767.27 | E11: =1-(D11-D10)/(B11-B10) -> 0.41178354
A12: rhodium100b low | B12: 444.92 | C12: 763.73 | D12: =C12*44/12 -> 2800.3433 | E12: =1-(D12-D11)/(B12-B11) -> -0.17115203
A13: rhodium100b high | B13: 550.54 | C13: 790.77 | D13: =C13*44/12 -> 2899.49 | E13: =1-(D13-D12)/(B13-B12) -> 0.061288897
A16: 2050
A17: Scenario | B17: CDR (Mt) | C17: C emissions (Mt C) | D17: C emission (Mt CO2-eq) | E17: Effectiveness of CDR
A18: 100 Mt baseline | B18: 100 | C18: -19.5 | D18: =C18*44/12 -> -71.5 | E18: N/A
A19: 500 Mt baseline | B19: 500 | C19: 40.97 | D19: =C19*44/12 -> 150.22333 | E19: =1-(D19-D18)/(B19-B18) -> 0.44569167
A20: rhodium100b low | B20: =B19+788.98 -> 1288.98 | C20: 218.8 | D20: =C20*44/12 -> 802.26667 | E20: =1-(D20-D19)/(B20-B19) -> 0.17356164
A21: 1500 Mt baseline | B21: 1500 | C21: 263.8 | D21: =C21*44/12 -> 967.26667 | E21: =1-(D21-D20)/(B21-B20) -> 0.21808359
A22: rhodium100b high | B22: =B21+638.54 -> 2138.54 | C22: 427.8 | D22: =C22*44/12 -> 1568.6 | E22: =1-(D22-D21)/(B22-B21) -> 0.058268341
A23: 2400 Mt baseline | B23: 2400 | C23: 496.9 | D23: =C23*44/12 -> 1821.9667 | E23: =1-(D23-D22)/(B23-B22) -> 0.030954384
A24: 4100 Mt baseline | B24: 4100 | C24: 1069.7 | D24: =C24*44/12 -> 3922.2333 | E24: =1-(D24-D23)/(B24-B23) -> -0.23545098

Sheet Net-Zero Mandate
A1: Scenario | B1: Baseline | C1: NPV of Net Zero Mandate | 2.0% | Trillion $USD | D1: 2% Discount Rate | E1: NPV of Net Zero Mandate | 12.0% | Trillion $USD | F1: 12% Discount Rate | G1: NPV of Net Zero Mandate | 20.0% | Trillion $USD | H1: 20% Discount Rate | I1: Cost of Mitigation in 2050 | J1: Abatement size in 2050 | M1: Median Under 12% | N1: Mean under 12% | O1: CI | P1: Lower Range | Q1: Upper Range
A2: 100 Mt Baseline | B2: 100 Mt | C2: 4.973084 | D2: =C2/C$2-1 -> 0 | E2: 1.0799998 | F2: =E2/E$2-1 -> 0 | G2: 0.44036245 | H2: =G2/G$2-1 -> 0 | I2: =J2/J$2-1 -> 0 | J2: 0.78955285 | M2: =MEDIAN(E3:E32)-E2 -> 0.044656436 | N2: =AVERAGE(E3:E32)-E2 -> 0.043674317 | O2: =_xlfn.CONFIDENCE.T(0.05, _xlfn.STDEV.S(E3:E32), COUNT(E3:E32)) -> 0.011247283 | P2: =N2-O2 -> 0.032427034 | Q2: =N2+O2 -> 0.0549216
A3: 45Q-2040 | B3: 500 Mt | C3: 5.0718252 | D3: =C3/C$2-1 -> 0.019855136 | E3: 1.1072255 | F3: =E3/E$2-1 -> 0.025209004 | G3: 0.4530906 | H3: =G3/G$2-1 -> 0.028903795 | I3: =J3/J$2-1 -> 0.010644546 | J3: 0.79795728
A4: 45Q-2050 | B4: 500 Mt | C4: 5.132098 | D4: =C4/C$2-1 -> 0.031974942 | E4: 1.1169337 | F4: =E4/E$2-1 -> 0.03419805 | G4: 0.45571975 | H4: =G4/G$2-1 -> 0.034874207 | I4: =J4/J$2-1 -> 0.019307501 | J4: 0.80479714
A5: CDRIA-2035 | B5: 500 Mt | C5: 5.0642413 | D5: =C5/C$2-1 -> 0.018330138 | E5: 1.1064186 | F5: =E5/E$2-1 -> 0.024461886 | G5: 0.45405916 | H5: =G5/G$2-1 -> 0.031103255 | I5: =J5/J$2-1 -> 0.010561719 | J5: 0.79789189
A6: CDRIA-2050 | B6: 500 Mt | C6: 4.8684535 | D6: =C6/C$2-1 -> -0.021039346 | E6: 1.0698338 | F6: =E6/E$2-1 -> -0.0094129782 | G6: 0.4413103 | H6: =G6/G$2-1 -> 0.002152415 | I6: =J6/J$2-1 -> -0.035505217 | J6: 0.76151961
A7: Innovation-DACHubs | B7: 500 Mt | C7: 5.0651494 | D7: =C7/C$2-1 -> 0.018512746 | E7: 1.1039788 | F7: =E7/E$2-1 -> 0.02220279 | G7: 0.45225596 | H7: =G7/G$2-1 -> 0.027008442 | I7: =J7/J$2-1 -> 0.012916267 | J7: 0.79975093
A8: Innovation-maintain | B8: 500 Mt | C8: 5.0631788 | D8: =C8/C$2-1 -> 0.018116493 | E8: 1.1020255 | F8: =E8/E$2-1 -> 0.020394201 | G8: 0.44986187 | H8: =G8/G$2-1 -> 0.021571818 | I8: =J8/J$2-1 -> 0.010368295 | J8: 0.79773917 | N8: St. Dev | O8: =_xlfn.STDEV.S(E3:E32) -> 0.030120777
A9: Innovation-rhodium18b | B9: 500 Mt | C9: 5.0717892 | D9: =C9/C$2-1 -> 0.019847894 | E9: 1.106818 | F9: =E9/E$2-1 -> 0.024831719 | G9: 0.45191984 | H9: =G9/G$2-1 -> 0.026245177 | I9: =J9/J$2-1 -> 0.0060288744 | J9: 0.79431297 | N9: Count | O9: =COUNT(E3:E32) -> 30
A10: Innovation-rhodium6b | B10: 500 Mt | C10: 5.0654758 | D10: =C10/C$2-1 -> 0.018578383 | E10: 1.103414 | F10: =E10/E$2-1 -> 0.021679854 | G10: 0.45035362 | H10: =G10/G$2-1 -> 0.022688516 | I10: =J10/J$2-1 -> 0.0086785676 | J10: 0.79640504
A11: Innovation-triple | B11: 500 Mt | C11: 5.0644696 | D11: =C11/C$2-1 -> 0.018376045 | E11: 1.1031712 | F11: =E11/E$2-1 -> 0.021454988 | G11: 0.45034165 | H11: =G11/G$2-1 -> 0.02266132 | I11: =J11/J$2-1 -> 0.0079536653 | J11: 0.79583269
A12: 500 Mt Baseline | B12: 500 Mt | C12: 5.064589 | D12: =C12/C$2-1 -> 0.018400051 | E12: 1.1015991 | F12: =E12/E$2-1 -> 0.019999392 | G12: 0.44981677 | H12: =G12/G$2-1 -> 0.021469396 | I12: =J12/J$2-1 -> 0.013462435 | J12: 0.80018215
A13: Procure3B | B13: 500 Mt | C13: 5.0805945 | D13: =C13/C$2-1 -> 0.021618485 | E13: 1.1122008 | F13: =E13/E$2-1 -> 0.029815748 | G13: 0.4566464 | H13: =G13/G$2-1 -> 0.036978517 | I13: =J13/J$2-1 -> 0.008799151 | J13: 0.79650025
A14: ProcureRhodium | B14: 500 Mt | C14: 5.2865615 | D14: =C14/C$2-1 -> 0.063034838 | E14: 1.1998079 | F14: =E14/E$2-1 -> 0.11093344 | G14: 0.51042752 | H14: =G14/G$2-1 -> 0.15910771 | I14: =J14/J$2-1 -> 0.0017531058 | J14: 0.79093702
A15: ProcureScaling | B15: 500 Mt | C15: 5.0709044 | D15: =C15/C$2-1 -> 0.019669981 | E15: 1.1061597 | F15: =E15/E$2-1 -> 0.024222186 | G15: 0.45247248 | H15: =G15/G$2-1 -> 0.027500134 | I15: =J15/J$2-1 -> 0.009890681 | J15: 0.79736207
A16: 45Q-2040 | B16: 1.5 Gt | C16: 5.1811748 | D16: =C16/C$2-1 -> 0.041843413 | E16: 1.1344926 | F16: =E16/E$2-1 -> 0.05045629 | G16: 0.46492194 | H16: =G16/G$2-1 -> 0.055771062 | I16: =J16/J$2-1 -> 0.015734259 | J16: 0.80197588
A17: 45Q-2050 | B17: 1.5 Gt | C17: 5.2414073 | D17: =C17/C$2-1 -> 0.053955125 | E17: 1.1459694 | F17: =E17/E$2-1 -> 0.061083029 | G17: 0.46833215 | H17: =G17/G$2-1 -> 0.063515173 | I17: =J17/J$2-1 -> 0.0098615794 | J17: 0.79733909
A18: CDRIA-2035 | B18: 1.5 Gt | C18: 5.1754847 | D18: =C18/C$2-1 -> 0.040699234 | E18: 1.1343809 | F18: =E18/E$2-1 -> 0.05035289 | G18: 0.46670096 | H18: =G18/G$2-1 -> 0.059810977 | I18: =J18/J$2-1 -> 0.01666728 | J18: 0.80271255
A19: CDRIA-2050 | B19: 1.5 Gt | C19: 4.8119662 | D19: =C19/C$2-1 -> -0.032397963 | E19: 1.0667309 | F19: =E19/E$2-1 -> -0.012285965 | G19: 0.44363875 | H19: =G19/G$2-1 -> 0.007440004 | I19: =J19/J$2-1 -> -0.040784874 | J19: 0.75735104
A20: 1500 Mt Baseline | B20: 1.5 Gt | C20: 5.2054763 | D20: =C20/C$2-1 -> 0.046730027 | E20: 1.131545 | F20: =E20/E$2-1 -> 0.04772712 | G20: 0.46163241 | H20: =G20/G$2-1 -> 0.048301023 | I20: =J20/J$2-1 -> 0.032111903 | J20: 0.8149069
A21: Innovation-DACHubs | B21: 1.5 Gt | C21: 5.2021279 | D21: =C21/C$2-1 -> 0.046056724 | E21: 1.1332403 | F21: =E21/E$2-1 -> 0.049296813 | G21: 0.46383228 | H21: =G21/G$2-1 -> 0.053296609 | I21: =J21/J$2-1 -> 0.030034552 | J21: 0.81326672
... A32: procure-scaling-maintain-h | B32: 1.5 Gt | C32: 5.1996173 | D32: =C32/C$2-1 -> 0.045551881 | E32: 1.1320707 | F32: =E32/E$2-1 -> 0.048213799 | G32: 0.46230704 | H32: =G32/G$2-1 -> 0.049833003 | I32: =J32/J$2-1 -> 0.039508684 | J32: 0.82074704
A35: 0.02 | B35: =B1 -> Baseline | C35: =D1 -> 2% Discount Rate | D35: =I1 -> Cost of Mitigation in 2050 | E35: Innovation Scenarios | F35: Subsidy Scenarios | G35: Procurement Scenarios | H35: Optimal Scenarios | I35: Baseline Pathways | J35: 100 Mt Baseline
A36: =A2 -> 100 Mt Baseline | B36: =B2 -> 100 Mt | C36: =D2 -> 0 | D36: =I2 -> 0 | J36: 0
A37: =A3 -> 45Q-2040 | B37: =B3 -> 500 Mt | C37: =D3 -> 0.019855136 | D37: =I3 -> 0.010644546 | F37: =C37 -> 0.019855136
A38: =A4 -> 45Q-2050 | B38: =B4 -> 500 Mt | C38: =D4 -> 0.031974942 | D38: =I4 -> 0.019307501 | F38: =C38 -> 0.031974942
A39: =A5 -> CDRIA-2035 | B39: =B5 -> 500 Mt | C39: =D5 -> 0.018330138 | D39: =I5 -> 0.010561719 | F39: =C39 -> 0.018330138
A40: =A6 -> CDRIA-2050 | B40: =B6 -> 500 Mt | C40: =D6 -> -0.021039346 | D40: =I6 -> -0.035505217 | F40: =C40 -> -0.021039346
A41: =A7 -> Innovation-DACHubs | B41: =B7 -> 500 Mt | C41: =D7 -> 0.018512746 | D41: =I7 -> 0.012916267 | E41: =C41 -> 0.018512746
A42: =A8 -> Innovation-maintain | B42: =B8 -> 500 Mt | C42: =D8 -> 0.018116493 | D42: =I8 -> 0.010368295 | E42: =C42 -> 0.018116493
A43: =A9 -> Innovation-rhodium18b | B43: =B9 -> 500 Mt | C43: =D9 -> 0.019847894 | D43: =I9 -> 0.0060288744 | E43: =C43 -> 0.019847894
A44: =A10 -> Innovation-rhodium6b | B44: =B10 -> 500 Mt | C44: =D10 -> 0.018578383 | D44: =I10 -> 0.0086785676 | E44: =C44 -> 0.018578383
A45: =A11 -> Innovation-triple | B45: =B11 -> 500 Mt | C45: =D11 -> 0.018376045 | D45: =I11 -> 0.0079536653 | E45: =C45 -> 0.018376045
A46: =A12 -> 500 Mt Baseline | B46: =B12 -> 500 Mt | C46: =D12 -> 0.018400051 | D46: =I12 -> 0.013462435 | I46: =C46 -> 0.018400051
A47: =A13 -> Procure3B | B47: =B13 -> 500 Mt | C47: =D13 -> 0.021618485 | D47: =I13 -> 0.008799151 | G47: =C47 -> 0.021618485
A48: =A14 -> ProcureRhodium | B48: =B14 -> 500 Mt | C48: =D14 -> 0.063034838 | D48: =I14 -> 0.0017531058 | G48: =C48 -> 0.063034838
A49: =A15 -> ProcureScaling | B49: =B15 -> 500 Mt | C49: =D15 -> 0.019669981 | D49: =I15 -> 0.009890681 | G49: =C49 -> 0.019669981
A50: =A16 -> 45Q-2040 | B50: =B16 -> 1.5 Gt | C50: =D16 -> 0.041843413 | D50: =I16 -> 0.015734259 | F50: =C50 -> 0.041843413
A51: =A17 -> 45Q-2050 | B51: =B17 -> 1.5 Gt | C51: =D17 -> 0.053955125 | D51: =I17 -> 0.0098615794 | F51: =C51 -> 0.053955125
A52: =A18 -> CDRIA-2035 | B52: =B18 -> 1.5 Gt | C52: =D18 -> 0.040699234 | D52: =I18 -> 0.01666728 | F52: =C52 -> 0.040699234
...

Sheet CDR Cost Reduction
A1: Scenario | B1: Baseline | D1: NPV of Net Zero Mandate | 2.0% | Trillion $USD | E1: 2% Discount Rate | F1: NPV of Net Zero Mandate | 12.0% | Trillion $USD | G1: 12% Discount Rate | H1: NPV of Net Zero Mandate | 20.0% | Trillion $USD | I1: 20% Discount Rate | J1: 2050 Snapshot | K1: Abatement size in 2050
A2: 100 Mt Baseline | B2: 100 Mt | D2: 4.973084 | F2: 1.0799998 | H2: 0.44036245 | K2: 0.78955285
A3: 45Q-2040 | B3: 500 Mt | C3: 0 | D3: 5.0718252 | E3: 27.621327 | F3: 1.1072255 | G3: 38.721957 | H3: 0.4530906 | I3: 43.944236 | J3: 10.903288 | K3: 0.79795728
A4: 45Q-2050 | B4: 500 Mt | D4: 5.132098 | E4: 95.027858 | F4: 1.1169337 | G4: 81.341564 | H4: 0.45571975 | I4: 66.213331 | J4: 77.537456 | K4: 0.80479714
A5: CDRIA-2035 | B5: 500 Mt | D5: 5.0642413 | E5: 23.265645 | F5: 1.1064186 | G5: 34.905619 | H5: 0.45405916 | I5: 47.160197 | J5: 10.777424 | K5: 0.79789189
A6: CDRIA-2050 | B6: 500 Mt
A7: Innovation-DACHubs | B7: 500 Mt | C7: 0 | D7: 5.0651494 | E7: 20.74039 | F7: 1.1039788 | G7: 25.534548 | H7: 0.45225596 | I7: 30.623023 | J7: 12.610154 | K7: 0.79975093
A8: Innovation-maintain | B8: 500 Mt | C8: 0 | D8: 5.0631788 | E8: 21.43401 | F8: 1.1020255 | G8: 24.666198 | H8: 0.44986187 | I8: 25.579182 | J8: 10.690108 | K8: 0.79773917
A9: Innovation-rhodium18b | B9: 500 Mt | C9: 0 | D9: 5.0717892 | E9: 25.551076 | F9: 1.106818 | G9: 32.946602 | H9: 0.45191984 | I9: 34.183176 | J9: 6.5878223 | K9: 0.79431297
A10: Innovation-rhodium6b | B10: 500 Mt | C10: 0 | D10: 5.0654758 | E10: 22.645549 | F10: 1.103414 | G10: 27.133311 | H10: 0.45035362 | I10: 27.845084 | J10: 9.0841009 | K10: 0.79640504
A11: Innovation-triple | B11: 500 Mt | C11: 0 | D11: 5.0644696 | E11: 22.761987 | F11: 1.1031712 | G11: 27.269938 | H11: 0.45034165 | I11: 28.329187 | J11: 8.5063978 | K11: 0.79583269
A12: 500 Mt Baseline | B12: 500 Mt | C12: 0 | D12: 5.064589 | E12: 20.584959 | F12: 1.1015991 | G12: 22.899922 | H12: 0.44981677 | I12: 24.134128 | J12: 13.137109 | K12: 0.80018216
A13: Procure3B | B13: 500 Mt | C13: 0 | D13: 5.0805945 | E13: 26.462965 | F13: 1.1122008 | G13: 38.516547 | H13: 0.4566464 | I13: 48.669566 | J13: 9.20062 | K13: 0.79650025
A14: ProcureRhodium | B14: 500 Mt | C14: 0 | D14: 5.2865615 | E14: 96.268213 | F14: 1.1998079 | G14: 236.62135 | H14: 0.51042752 | I14: 515.18468 | J14: 1.9261438 | K14: 0.79093702
A15: ProcureScaling | B15: 500 Mt | C15: 0 | D15: 5.0709044 | E15: 23.476397 | F15: 1.1061597 | G15: 29.835672 | H15: 0.45247248 | I15: 33.564099 | J15: 10.199345 | K15: 0.79736207
A16: 45Q-2040 | B16: 1.5 Gt | C16: 0 | D16: 5.1811748 | E16: 20.445963 | F16: 1.1344926 | G16: 33.296986 | H16: 0.46492194 | I16: 45.482461 | J16: 4.2929028 | K16: 0.80197588
A17: 45Q-2050 | B17: 1.5 Gt | C17: 0 | D17: 5.2414073 | E17: 62.001489 | F17: 1.1459694 | G17: 73.808838 | H17: 0.46833215 | I17: 75.181946 | J17: 9.004161 | K17: 0.79733909
A18: CDRIA-2035 | B18: 1.5 Gt | C18: 0 | D18: 5.1754847 | E18: 18.358117 | F18: 1.1343809 | G18: 29.945424 | H18: 0.46670096 | I18: 44.971999 | J18: 4.5299327 | K18: 0.80271255
A19: CDRIA-2050 | B19: 1.5 Gt
A20: 1500 Mt Baseline | B20: 1.5 Gt | C20: 0 | D20: 5.2054763 | E20: 19.569169 | F20: 1.131545 | G20: 24.779534 | H20: 0.46163241 | I20: 29.445243 | J20: 8.4504573 | K20: 0.8149069
A21: Innovation-DACHubs | B21: 1.5 Gt | C21: 0 | D21: 5.2021279 | E21: 19.347935 | F21: 1.1332403 | G21: 25.703142 | H21: 0.46383228 | I21: 32.714647 | J21: 7.9367565 | K21: 0.81326672
A22: Innovation-maintain | B22: 1.5 Gt | C22: 0 | D22: 5.172028 | E22: 17.426438 | F22: 1.1272007 | G22: 23.678535 | H22: 0.46032657 | I22: 28.918131 | J22: 4.5221189 | K22: 0.80266837
A23: Innovation-rhodium18b | B23: 1.5 Gt | C23: 0 | D23: 5.1380938 | E23: 15.272034 | F23: 1.124903 | G23: 24.125784 | H23: 0.46008383 | I23: 30.949524 | J23: -0.46285562 | K23: 0.78825855
A24: Innovation-rhodium6b | B24: 1.5 Gt | C24: 0 | D24: 5.1823334 | E24: 18.71138 | F24: 1.1285106 | G24: 24.987148 | H24: 0.4604398 | I24: 29.987807 | J24: 7.1441239 | K24: 0.81001935
A25: Innovation-triple | B25: 1.5 Gt | C25: 0 | D25: 5.1482869 | E25: 15.835044 | F25: 1.1244094 | G25: 23.117427 | H25: 0.45961217 | I25: 29.111209 | J25: 1.4728076 | K25: 0.79372266
A26: Procure3B | B26: 1.5 Gt | C26: 0 | D26: 5.1755467 | E26: 18.116869 | F26: 1.1348238 | G26: 28.633791 | H26: 0.46619515 | I26: 40.074512 | J26: 3.0910263 | K26: 0.79842428
A27: ProcureRhodium | B27: 1.5 Gt | C27: 0 | D27: 5.3051977 | E27: 33.128009 | F27: 1.2083411 | G27: 81.360566 | H27: 0.51586885 | I27: 164.08104 | J27: 1.3040601 | K27: 0.79301345
A28: ProcureScaling | B28: 1.5 Gt | C28: 0 | D28: 5.1756638 | E28: 17.850557 | F28: 1.1303866 | G28: 25.600126 | H28: 0.46253652 | I28: 32.824176 | J28: 4.2508096 | K28: 0.80187562
A29: 45Q-2040-maintain-l | B29: 500 Mt | D29: 5.0725827 | E29: 29.823509 | F29: 1.1081363 | G29: 43.116454 | H29: 0.45332284 | I29: 48.172776 | J29: 8.4505068 | K29: 0.77221662
A30: procure-scaling-maintain-h | B30: 1.5 Gt | C30: 0 | D30: 5.1996173 | E30: 20.970243 | F30: 1.1320707 | G30: 27.824135 | H30: 0.46230704 | I30: 34.255472 | J30: 11.37093 | K30: 1.0342522
K31: 0.79572708
K32: 0.82074704
A34: 2.4 Gt Baseline | B34: 2.4 Gt | C34: 0 | D34: 5.1707489 | E34: 10.355322 | F34: 1.1354049 | G34: 17.558328 | H34: 0.46694231 | I34: 25.800721 | J34: -3.2995586
A35: 4.1 Gt Baseline | B35: 4.1 Gt | C35: 0 | D35: 5.4085868 | E35: 12.773169 | F35: 1.1700899 | G35: 17.155655 | H35: 0.47878614 | I35: 24.321572 | J35: 23.659543
