Workbook

Sheet Baseline Parameters
A1: Tech | B1: DAC (sorbent) | C1: DAC (solvent) | D1: TEW (Nature Paper) | E1: TEW (Ours) - less input costs | F1: OEW | G1: BECCS | H1: BECCS | J1: Nothing | K1: Low | L1: High | M1: Very High
A2: 2025 | B2: 446 | C2: 209 | D2: =D$13*EXP(D$14*($A2-$A$3)) -> 316.03816 | E2: =E$13*EXP(E$14*($A2-$A$3)) -> 269.98072 | F2: 140 | G2: 232 | H2: =G2/6.1/1000*44/12 -> 0.13945355 | J2: 13.5 | K2: 13.5 | L2: 13.5 | M2: 13.5
A3: 2030 | B3: =B$13*EXP(B$14*($A3-$A$2)) -> 380.16958 | C3: =C$13*EXP(C$14*($A3-$A$2)) -> 178.15122 | D3: 265 | E3: =0.125*6.1*12/44*1000 -> 207.95455 | F3: =F$13*EXP(F$14*($A3-$A$2)) -> 126.10086 | G3: 212 | H3: =G3/6.1/1000*44/12 -> 0.12743169 | J3: =J$13*EXP(J$14*($A3-$A$2)) -> 20.149627 | K3: =K$13*EXP(K$14*($A3-$A$2)) -> 27.801038 | L3: =L$13*EXP(L$14*($A3-$A$2)) -> 34.632614 | M3: =M$13*EXP(M$14*($A3-$A$2)) -> 38.046023
A4: 2035 | B4: =B$13*EXP(B$14*($A4-$A$2)) -> 324.05585 | C4: =C$13*EXP(C$14*($A4-$A$2)) -> 151.85577 | D4: =D$13*EXP(D$14*($A4-$A$3)) -> 222.20418 | E4: =E$13*EXP(E$14*($A4-$A$3)) -> 160.17845 | F4: =F$13*EXP(F$14*($A4-$A$2)) -> 113.58162 | G4: =G$13*EXP(G$14*($A4-$A$2)) -> 193.72414 | H4: =G4/6.1/1000*44/12 -> 0.1164462 | J4: =J$13*EXP(J$14*($A4-$A$2)) -> 30.074628 | K4: =K$13*EXP(K$14*($A4-$A$2)) -> 57.251684 | L4: =L$13*EXP(L$14*($A4-$A$2)) -> 88.845772 | M4: =M$13*EXP(M$14*($A4-$A$2)) -> 107.22221
A5: 2040 | B5: =B$13*EXP(B$14*($A5-$A$2)) -> 276.22461 | C5: =C$13*EXP(C$14*($A5-$A$2)) -> 129.44158 | D5: =D$13*EXP(D$14*($A5-$A$3)) -> 186.31962 | E5: =E$13*EXP(E$14*($A5-$A$3)) -> 123.37857 | F5: =F$13*EXP(F$14*($A5-$A$2)) -> 102.30529 | G5: =G$13*EXP(G$14*($A5-$A$2)) -> 177.02378 | H5: =G5/6.1/1000*44/12 -> 0.10640774 | J5: =J$13*EXP(J$14*($A5-$A$2)) -> 44.888336 | K5: =K$13*EXP(K$14*($A5-$A$2)) -> 117.90046 | L5: =L$13*EXP(L$14*($A5-$A$2)) -> 227.92306 | M5: =M$13*EXP(M$14*($A5-$A$2)) -> 302.1762
A6: 2045 | B6: =B$13*EXP(B$14*($A6-$A$2)) -> 235.45335 | C6: =C$13*EXP(C$14*($A6-$A$2)) -> 110.33576 | D6: =D$13*EXP(D$14*($A6-$A$3)) -> 156.23018 | E6: =E$13*EXP(E$14*($A6-$A$3)) -> 95.033214 | F6: =F$13*EXP(F$14*($A6-$A$2)) -> 92.14846 | G6: =G$13*EXP(G$14*($A6-$A$2)) -> 161.76311 | H6: =G6/6.1/1000*44/12 -> 0.097234657 | J6: =J$13*EXP(J$14*($A6-$A$2)) -> 66.998758 | K6: =K$13*EXP(K$14*($A6-$A$2)) -> 242.79669 | L6: =L$13*EXP(L$14*($A6-$A$2)) -> 584.70898 | M6: =M$13*EXP(M$14*($A6-$A$2)) -> 851.60018
A7: 2050 | B7: =B2*B17 -> 200.7 | C7: =C2*C17 -> 94.05 | D7: 131 | E7: =0.044*6.1*12/44*1000 -> 73.2 | F7: 83 | G7: =G$13*EXP(G$14*($A7-$A$2)) -> 147.81801 | H7: =G7/6.1/1000*44/12 -> 0.088852359 | J7: 100 | K7: 500 | L7: 1500 | M7: 2400
A8: Source | B8: R2R | C8: R2R | D8: https://www.nature.com/articles/s41586-024-08429-2.pdf | E8: https://www.nature.com/articles/s41586-024-08429-2.pdf | F8: https://iopscience.iop.org/article/10.1088/1748-9326/ad5192/pdf | G8: CDR Price Survey White Paper-Email.pdf | J8: N/A | K8: N/A | L8: N/A | M8: N/A
A9: Page | B9: 7-11 | C9: 7-11 | D9: 432 | E9: 432 | F9: 8 | G9: 4
A10: Notes | B10: Less heat and electric | C10: Less heat and electric | D10: Illinois 2030 and 2050 from Figure 5c less costs (TEW worksheet) | E10: Illinois 2030 and 2050 from Figure 5c less costs (TEW worksheet) | F10: Fixed costs (low-carbon scenario
A11: Units | B11: 2025$/t CO2-eq | C11: 2025$/t CO2-eq | D11: 2025$/t CO2-eq | E11: 2025$/t CO2-eq | F11: 2025$/t CO2-eq | G11: 2025$/t CO2-eq | H11: 1975 USD/t C | J11: Mt CO2-eq | K11: Mt CO2-eq | L11: Mt CO2-eq
A13: A | B13: =EXP(LN(B2)-B14*0) -> 446 | C13: =EXP(LN(C2)-C14*0) -> 209 | D13: =EXP(LN(D3)-D14*0) -> 265 | E13: =EXP(LN(E3)-E14*0) -> 207.95455 | F13: =EXP(LN(F2)-F14*0) -> 140 | G13: =EXP(LN(G2)-G14*0) -> 232 | J13: =EXP(LN(J2)-J14*0) -> 13.5 | K13: =EXP(LN(K2)-K14*0) -> 13.5 | L13: =EXP(LN(L2)-L14*0) -> 13.5 | M13: =EXP(LN(M2)-M14*0) -> 13.5
A14: B | B14: =(LN(B2)-LN(B7))/($A2-$A7) -> -0.031940308 | C14: =(LN(C2)-LN(C7))/($A2-$A7) -> -0.031940308 | D14: =(LN(D3)-LN(D7))/($A3-$A7) -> -0.035226625 | E14: =(LN(E3)-LN(E7))/($A3-$A7) -> -0.052206205 | F14: =(LN(F2)-LN(F7))/($A2-$A7) -> -0.020912073 | G14: =(LN(G2)-LN(G3))/($A2-$A3) -> -0.018030219 | J14: =(LN(J2)-LN(J7))/($A2-$A7) -> 0.08009922 | K14: =(LN(K2)-LN(K7))/($A2-$A7) -> 0.14447674 | L14: =(LN(L2)-LN(L7))/($A2-$A7) -> 0.18842123 | M14: =(LN(M2)-LN(M7))/($A2-$A7) -> 0.20722137
A17: Ultimate reduction in cost | B17: 0.45 | C17: 0.45 | I17: 2025 source | J17: Rhodium 2024 | K17: Rhodium 2024 | L17: Rhodium 2024
A18: Years | B18: 25 | C18: 25 | I18: Page | J18: 42 | K18: 42 | L18: 42
A19: Source | B19: Rhodium 2024 | C19: Rhodium 2024
A20: Page | B20: 44 | C20: 44

Sheet Learning Rates
A1: Data | H1: All Technologies | I1: BECCS | J1: DAC Sorbent | K1: DAC Solvent | L1: TEW | M1: OEW | N1: All CDR | P1: CDR Policy Scenarios | Q1: Policy 1 | R1: Policy 2 | S1: Policy 3 | T1: Policy 4 | U1: Policy 5 | V1: Policy 6 | Y1: Year | Z1: CDR R&D | AA1: Source
A2: Learning by research rates | B2: Elasticity | C2: Comp | D2: Source | H2: Learning Rate | I2: =1-2^I3 -> 0.049999617 | J2: =1-2^J3 -> 0.049999617 | K2: =1-2^K3 -> 0.049999617 | L2: =1-2^L3 -> 0.049999617 | M2: =1-2^M3 -> 0.049999617 | N2: =1-2^N3 -> 0.049999617 | P2: Learning Rate | Q2: =1-2^Q3 -> 0.049999617 | R2: =1-2^R3 -> 0.049999617 | S2: =1-2^S3 -> 0.049999617 | T2: =1-2^T3 -> 0.049999617 | U2: =1-2^U3 -> 0.049999617 | V2: =1-2^V3 -> 0.049999617 | Y2: 2009-2018 | Z2: 1045 | AA2: https://bipartisanpolicy.org/download/?file=/wp-content/uploads/2019/06/Carbon-Removal-Comparing-Historical-Investments-with-the-National-Academies-Recommendations.pdf
A3: 0.049 | B3: -0.072 | C3: Offshore wind | D3: https://journals.sagepub.com/doi/pdf/10.5547/ISSN0195-6574-EJ-Vol28-No3-4 | E3: Learning by research (table 4 and 5) | H3: Learning Elasticity | I3: -0.074 | J3: -0.074 | K3: -0.074 | L3: -0.074 | M3: -0.074 | N3: -0.074 | P3: Learning Elasticity | Q3: -0.074 | R3: -0.074 | S3: -0.074 | T3: -0.074 | U3: -0.074 | V3: -0.074 | Y3: 2019 | Z3: 104 | AA3: Same as 2022 non-supplemental investments
A4: 0.053 | B4: -0.078 | C4: thermal solar | D4: https://journals.sagepub.com/doi/pdf/10.5547/ISSN0195-6574-EJ-Vol28-No3-4 | E4: Learning by research (table 4 and 5) | H4: Cumulative Public R&D | I4: =$Z$9 -> 1719 | J4: =$Z$9 -> 1719 | K4: =$Z$9 -> 1719 | L4: =$Z$9 -> 1719 | M4: =$Z$9 -> 1719 | N4: =$Z$9 -> 1719 | P4: Cumulative Public R&D (Million USD) | Q4: =$Z$9 -> 1719 | R4: =Q4 -> 1719 | S4: =R4 -> 1719 | T4: =S4 -> 1719 | U4: =T4 -> 1719 | V4: =T4 -> 1719 | Y4: 2020 | Z4: 104 | AA4: Same as 2022 non-supplemental investments
A5: 0.268 | B5: -0.45 | C5: wind power | D5: https://journals.sagepub.com/doi/pdf/10.5547/ISSN0195-6574-EJ-Vol28-No3-4 | E5: Learning by research (table 4 and 5) | H5: Alpha | P5: Alpha | Y5: 2021 | Z5: 104 | AA5: Same as 2022 non-supplemental investments
A6: 0.437 | B6: -0.829 | C6: waste to electricity | D6: https://journals.sagepub.com/doi/pdf/10.5547/ISSN0195-6574-EJ-Vol28-No3-4 | E6: Learning by research (table 4 and 5) | H6: Year | I6: BECCS | J6: DAC Sorbent | K6: DAC Solvent | L6: TEW | M6: OEW | N6: All CDR | P6: Year | Q6: Rhodium $6B | R6: Maintain current appropriations | S6: Triple R&D | T6: DAC Hubs (Sorbent) | U6: DAC Hubs (Solvent) | V6: Rhodium $18B | Y6: 2022 | Z6: 104 | AA6: https://www.congress.gov/crs-product/IF11861#:~:text=For%20carbon%20removal%2C%20Congress%
H7: 2025 | I7: =I34/(I$4^I$3) -> 402.62283 | J7: =J34/(J$4^J$3) -> 774.00769 | K7: =K34/(K$4^K$3) -> 362.70764 | L7: =L34/(L$4^L$3) -> 468.53622 | M7: =M34/(M$4^M$3) -> 242.96205 | N7: =N34/(N$4^N$3) -> 625.63624 | P7: 2025 | Q7: =Q34/(Q$4^Q$3) -> 625.63624 | R7: =R34/(R$4^R$3) -> 625.63624 | S7: =S34/(S$4^S$3) -> 625.63624 | T7: =T34/(T$4^T$3) -> 774.00769 | U7: =U34/(U$4^U$3) -> 362.70764 | V7: =V34/(V$4^V$3) -> 625.63624 | Y7: 2023 | Z7: 140 | AA7: https://www.congress.gov/crs-product/IF11861#:~:text=For%20carbon%20removal%2C%20Congress%
A8: R&D to early market formation | C8: Early market formation to full commercialization | D8: Comp | E8: Source | H8: 2030 | I8: =I35/(I$4^I$3) -> 367.91397 | J8: =J35/(J$4^J$3) -> 659.76273 | K8: =K35/(K$4^K$3) -> 309.17132 | L8: =L35/(L$4^L$3) -> 360.89331 | M8: =M35/(M$4^M$3) -> 218.84088 | N8: =N35/(N$4^N$3) -> 515.10827 | P8: 2030 | Q8: =Q35/(Q$4^Q$3) -> 515.10827 | R8: =R35/(R$4^R$3) -> 515.10827 | S8: =S35/(S$4^S$3) -> 515.10827 | T8: =T35/(T$4^T$3) -> 659.76273 | U8: =U35/(U$4^U$3) -> 309.17132 | V8: =V35/(V$4^V$3) -> 515.10827 | Y8: 2024 | Z8: 118 | AA8: https://www.congress.gov/crs-product/IF11861#:~:text=For%20carbon%20removal%2C%20Congress%
A9: 10-44% | C9: 0.03 | D9: Wind | E9: Impacts of innovation on renewable energy technology cost reductions | F9: Table 2 | H9: 2035 | I9: =I36/(I$4^I$3) -> 336.19725 | J9: =J36/(J$4^J$3) -> 562.38053 | K9: =K36/(K$4^K$3) -> 263.53707 | L9: =L36/(L$4^L$3) -> 277.98061 | M9: =M36/(M$4^M$3) -> 197.11445 | N9: =N36/(N$4^N$3) -> 383.20139 | P9: 2035 | Q9: =Q36/(Q$4^Q$3) -> 383.20139 | R9: =R36/(R$4^R$3) -> 383.20139 | S9: =S36/(S$4^S$3) -> 383.20139 | T9: =T36/(T$4^T$3) -> 562.38053 | U9: =U36/(U$4^U$3) -> 263.53707 | V9: =V36/(V$4^V$3) -> 383.20139 | Y9: Total | Z9: =SUM(Z2:Z8) -> 1719
A10: 3-14% | D10: Wind | E10: Impacts of innovation on renewable energy technology cost reductions | F10: Table 2 | H10: 2040 | I10: =I37/(I$4^I$3) -> 307.21473 | J10: =J37/(J$4^J$3) -> 479.37213 | K10: =K37/(K$4^K$3) -> 224.63851 | L10: =L37/(L$4^L$3) -> 214.11651 | M10: =M37/(M$4^M$3) -> 177.54502 | N10: =N37/(N$4^N$3) -> 351.43676 | P10: 2040 | Q10: =Q37/(Q$4^Q$3) -> 351.43676 | R10: =R37/(R$4^R$3) -> 351.43676 | S10: =S37/(S$4^S$3) -> 351.43676 | T10: =T37/(T$4^T$3) -> 479.37213 | U10: =U37/(U$4^U$3) -> 224.63851 | V10: =V37/(V$4^V$3) -> 351.43676
C11: 4-5% | D11: Wind | E11: Impacts of innovation on renewable energy technology cost reductions | F11: Table 3 | H11: 2045 | I11: =I38/(I$4^I$3) -> 280.7307 | J11: =J38/(J$4^J$3) -> 408.61592 | K11: =K38/(K$4^K$3) -> 191.48145 | L11: =L38/(L$4^L$3) -> 164.92475 | M11: =M38/(M$4^M$3) -> 159.91842 | N11: =N38/(N$4^N$3) -> 320.45154 | P11: 2045 | Q11: =Q38/(Q$4^Q$3) -> 320.45154 | R11: =R38/(R$4^R$3) -> 320.45154 | S11: =S38/(S$4^S$3) -> 320.45154 | T11: =T38/(T$4^T$3) -> 408.61592 | U11: =U38/(U$4^U$3) -> 191.48145 | V11: =V38/(V$4^V$3) -> 320.45154
C12: 0.05 | D12: Solar | E12: Impacts of innovation on renewable energy technology cost reductions | F12: Table 3 | H12: 2050 | I12: =I39/(I$4^I$3) -> 256.52977 | J12: =J39/(J$4^J$3) -> 348.30346 | K12: =K39/(K$4^K$3) -> 163.21844 | L12: =L39/(L$4^L$3) -> 127.03445 | M12: =M39/(M$4^M$3) -> 144.04179 | N12: =N39/(N$4^N$3) -> 300.11679 | P12: 2050 | Q12: =Q39/(Q$4^Q$3) -> 300.11679 | R12: =R39/(R$4^R$3) -> 300.11679 | S12: =S39/(S$4^S$3) -> 300.11679 | T12: =T39/(T$4^T$3) -> 348.30346 | U12: =U39/(U$4^U$3) -> 163.21844 | V12: =V39/(V$4^V$3) -> 300.11679
A13: Testing Equations
A14: Learning Rate Verification | B14: Offshore wind | C14: thermal solar | D14: wind power | E14: waste to electricity | H14: Additional R&D Spending (2025 Million USD) | P14: Additional R&D Spending (2025 Million USD)
A15: alpha | B15: =B18/(B16^B17) -> 3084.0999 | C15: =C18/(C16^C17) -> 9616.9213 | D15: =D18/(D16^D17) -> 113244.05 | E15: =E18/(E16^E17) -> 12395053 | H15: Year | I15: BECCS | J15: DAC Sorbent | K15: DAC Solvent | L15: TEW | M15: OEW | N15: All CDR | P15: Year | Q15: Rhodium $6B | R15: Maintain current appropriations | S15: Triple R&D | T15: DAC Hubs (Sorbent) | U15: DAC Hubs (Solvent) | V15: Rhodium $18B
A16: Public R&D | B16: 261 | C16: 4498 | D16: 7099 | E16: 18928 | H16: 2025 | I16: 100 | J16: 0 | K16: 100 | L16: 600 | M16: 100 | N16: 400 | P16: 2025 | Q16: 0 | R16: 118 | S16: =R16*3 -> 354 | T16: 700 | U16: 700 | V16: 0
A17: elasticity | B17: =B3 -> -0.072 | C17: =B4 -> -0.078 | D17: =B5 -> -0.45 | E17: =B6 -> -0.829 | H17: 2030 | I17: 0 | J17: 300 | K17: 200 | L17: 500 | M17: 100 | N17: 400 | P17: 2030 | Q17: 600 | R17: 118 | S17: =R17*3 -> 354 | T17: 0 | U17: 0 | V17: 1800
A18: c | B18: 2066 | C18: 4990 | D18: 2094 | E18: 3528 | H18: 2035 | I18: 0 | J18: 300 | K18: 300 | L18: 400 | M18: 100 | N18: 400 | P18: 2035 | Q18: 600 | R18: 118 | S18: =R18*3 -> 354 | T18: 0 | U18: 0 | V18: 1800
A19: After 100 $ 100 mil in investment | H19: 2040 | I19: 0 | J19: 0 | K19: 400 | L19: 300 | M19: 100 | N19: 400 | P19: 2040 | Q19: 0 | R19: 118 | S19: =R19*3 -> 354 | T19: 0 | U19: 0 | V19: 0
A20: alpha | B20: =B15 -> 3084.0999 | C20: =C15 -> 9616.9213 | D20: =D15 -> 113244.05 | E20: =E15 -> 12395053 | H20: 2045 | I20: 0 | J20: 0 | K20: 500 | L20: 200 | M20: 100 | N20: 400 | P20: 2045 | Q20: 0 | R20: 118 | S20: =R20*3 -> 354 | T20: 0 | U20: 0 | V20: 0
A21: Public R&D | B21: =B16+100 -> 361 | C21: =C16+100 -> 4598 | D21: =D16+100 -> 7199 | E21: =E16+100 -> 19028 | H21: 2050 | I21: 0 | J21: 0 | K21: 600 | L21: 100 | M21: 100 | N21: 400 | P21: 2050 | Q21: 0 | R21: 118 | S21: =R21*3 -> 354 | T21: 0 | U21: 0 | V21: 0
A22: elasticity | B22: =B17 -> -0.072 | C22: =C17 -> -0.078 | D22: =D17 -> -0.45 | E22: =E17 -> -0.829 | P22: Source | Q22: Rhodium (2024) | R22: CATF (2025) | S22: CATF (2025) | T22: CATF (2025) | U22: CATF (2025) | V22: Rhodium (2024)
A23: c | B23: =B20*(B21^B22) -> 2018.3102 | C23: =C20*(C21^C22) -> 4981.4489 | D23: =D20*(D21^D22) -> 2080.8603 | E23: =E20*(E21^E22) -> 3512.6225 | H23: Cumulative R&D Spending (2025 Million USD) | P23: Cumulative R&D Spending (2025 Million USD)
H24: Year | I24: BECCS | J24: DAC Sorbent | K24: DAC Solvent | L24: TEW | M24: OEW | N24: All CDR | P24: Year | Q24: Rhodium $6B | R24: Maintain current appropriations | S24: Triple R&D | T24: DAC Hubs (Sorbent) | U24: DAC Hubs (Solvent) | V24: Rhodium $18B
H25: 2025 | I25: =I4+I16*5 -> 2219 | J25: =J4+J16*5 -> 1719 | K25: =K4+K16*5 -> 2219 | L25: =L4+L16*5 -> 4719 | M25: =M4+M16*5 -> 2219 | N25: =N4+N16*5 -> 3719 | P25: 2025 | Q25: =Q4+Q16*5 -> 1719 | R25: =R4+R16*5 -> 2309 | S25: =S4+S16*5 -> 3489 | T25: =T4+T16*5 -> 5219 | U25: =U4+U16*5 -> 5219 | V25: =V4+V16*5 -> 1719
H26: 2030 | I26: =I25+I17*5 -> 2219 | J26: =J25+J17*5 -> 3219 | K26: =K25+K17*5 -> 3219 | L26: =L25+L17*5 -> 7219 | M26: =M25+M17*5 -> 2719 | N26: =N25+N17*5 -> 5719 | P26: 2030 | Q26: =Q25+Q17*5 -> 4719 | R26: =R25+R17*5 -> 2899 | S26: =S25+S17*5 -> 5259 | T26: =T25+T17*5 -> 5219 | U26: =U25+U17*5 -> 5219 | V26: =V25+V17*5 -> 10719
H27: 2035 | I27: =I26+I18*5 -> 2219 | J27: =J26+J18*5 -> 4719 | K27: =K26+K18*5 -> 4719 | L27: =L26+L18*5 -> 9219 | M27: =M26+M18*5 -> 3219 | N27: =N26+N18*5 -> 7719 | P27: 2035 | Q27: =Q26+Q18*5 -> 7719 | R27: =R26+R18*5 -> 3489 | S27: =S26+S18*5 -> 7029 | T27: =T26+T18*5 -> 5219 | U27: =U26+U18*5 -> 5219 | V27: =V26+V18*5 -> 19719
H28: 2040 | I28: =I27+I19*5 -> 2219 | J28: =J27+J19*5 -> 4719 | K28: =K27+K19*5 -> 6719 | L28: =L27+L19*5 -> 10719 | M28: =M27+M19*5 -> 3719 | N28: =N27+N19*5 -> 9719 | P28: 2040 | Q28: =Q27+Q19*5 -> 7719 | R28: =R27+R19*5 -> 4079 | S28: =S27+S19*5 -> 8799 | T28: =T27+T19*5 -> 5219 | U28: =U27+U19*5 -> 5219 | V28: =V27+V19*5 -> 19719
H29: 2045 | I29: =I28+I20*5 -> 2219 | J29: =J28+J20*5 -> 4719 | K29: =K28+K20*5 -> 9219 | L29: =L28+L20*5 -> 11719 | M29: =M28+M20*5 -> 4219 | N29: =N28+N20*5 -> 11719 | P29: 2045 | Q29: =Q28+Q20*5 -> 7719 | R29: =R28+R20*5 -> 4669 | S29: =S28+S20*5 -> 10569 | T29: =T28+T20*5 -> 5219 | U29: =U28+U20*5 -> 5219 | V29: =V28+V20*5 -> 19719
H30: 2050 | I30: =I29+I21*5 -> 2219 | J30: =J29+J21*5 -> 4719 | K30: =K29+K21*5 -> 12219 | L30: =L29+L21*5 -> 12219 | M30: =M29+M21*5 -> 4719 | N30: =N29+N21*5 -> 13719 | P30: 2050 | Q30: =Q29+Q21*5 -> 7719 | R30: =R29+R21*5 -> 5259 | S30: =S29+S21*5 -> 12339 | T30: =T29+T21*5 -> 5219 | U30: =U29+U21*5 -> 5219 | V30: =V29+V21*5 -> 19719
H32: Baseline Costs (2025USD/t CDR) | P32: Baseline Costs (2025USD/t CDR)
H33: Year | I33: BECCS | J33: DAC Sorbent | K33: DAC Solvent | L33: TEW | M33: OEW | N33: All CDR | P33: Year | Q33: Rhodium $6B | R33: Maintain current appropriations | S33: Triple R&D | T33: DAC Hubs (Sorbent) | U33: DAC Hubs (Solvent) | V33: Rhodium $18B
H34: 2025 | I34: ='Baseline Parameters'!G2 -> 232 | J34: ='Baseline Parameters'!B2 -> 446 | K34: ='Baseline Parameters'!C2 -> 209 | L34: ='Baseline Parameters'!E2 -> 269.98072 | M34: ='Baseline Parameters'!F2 -> 140 | N34: =Procurement!J3 -> 360.50516 | P34: 2025 | Q34: =$N34 -> 360.50516 | R34: =$N34 -> 360.50516 | S34: =$N34 -> 360.50516 | T34: =J34 -> 446 | U34: =K34 -> 209 | V34: =$N34 -> 360.50516
H35: 2030 | I35: ='Baseline Parameters'!G3 -> 212 | J35: ='Baseline Parameters'!B3 -> 380.16958 | K35: ='Baseline Parameters'!C3 -> 178.15122 | L35: ='Baseline Parameters'!E3 -> 207.95455 | M35: ='Baseline Parameters'!F3 -> 126.10086 | N35: =Procurement!J4 -> 296.81655 | P35: 2030 | Q35: =$N35 -> 296.81655 | R35: =$N35 -> 296.81655 | S35: =$N35 -> 296.81655 | T35: =J35 -> 380.16958 | U35: =K35 -> 178.15122 | V35: =$N35 -> 296.81655
H36: 2035 | I36: ='Baseline Parameters'!G4 -> 193.72414 | J36: ='Baseline Parameters'!B4 -> 324.05585 | K36: ='Baseline Parameters'!C4 -> 151.85577 | L36: ='Baseline Parameters'!E4 -> 160.17845 | M36: ='Baseline Parameters'!F4 -> 113.58162 | N36: =Procurement!J5 -> 220.80895 | P36: 2035 | Q36: =$N36 -> 220.80895 | R36: =$N36 -> 220.80895 | S36: =$N36 -> 220.80895 | T36: =J36 -> 324.05585 | U36: =K36 -> 151.85577 | V36: =$N36 -> 220.80895
H37: 2040 | I37: ='Baseline Parameters'!G5 -> 177.02378 | J37: ='Baseline Parameters'!B5 -> 276.22461 | K37: ='Baseline Parameters'!C5 -> 129.44158 | L37: ='Baseline Parameters'!E5 -> 123.37857 | M37: ='Baseline Parameters'!F5 -> 102.30529 | N37: =Procurement!J6 -> 202.50547 | P37: 2040 | Q37: =$N37 -> 202.50547 | R37: =$N37 -> 202.50547 | S37: =$N37 -> 202.50547 | T37: =J37 -> 276.22461 | U37: =K37 -> 129.44158 | V37: =$N37 -> 202.50547
H38: 2045 | I38: ='Baseline Parameters'!G6 -> 161.76311 | J38: ='Baseline Parameters'!B6 -> 235.45335 | K38: ='Baseline Parameters'!C6 -> 110.33576 | L38: ='Baseline Parameters'!E6 -> 95.033214 | M38: ='Baseline Parameters'!F6 -> 92.14846 | N38: =Procurement!J7 -> 184.65112 | P38: 2045 | Q38: =$N38 -> 184.65112 | R38: =$N38 -> 184.65112 | S38: =$N38 -> 184.65112 | T38: =J38 -> 235.45335 | U38: =K38 -> 110.33576 | V38: =$N38 -> 184.65112
H39: 2050 | I39: ='Baseline Parameters'!G7 -> 147.81801 | J39: ='Baseline Parameters'!B7 -> 200.7 | K39: ='Baseline Parameters'!C7 -> 94.05 | L39: ='Baseline Parameters'!E7 -> 73.2 | M39: ='Baseline Parameters'!F7 -> 83 | N39: =Procurement!J8 -> 172.9338 | P39: 2050 | Q39: =$N39 -> 172.9338 | R39: =$N39 -> 172.9338 | S39: =$N39 -> 172.9338 | T39: =J39 -> 200.7 | U39: =K39 -> 94.05 | V39: =$N39 -> 172.9338
H41: Updated Costs (2025USD/t CDR) | P41: Updated Costs (2025USD/t CDR)
H42: Year | I42: BECCS | J42: DAC Sorbent | K42: DAC Solvent | L42: TEW | M42: OEW | N42: All CDR | P42: Year | Q42: Rhodium $6B | R42: Maintain current appropriations | S42: Triple R&D | T42: DAC Hubs (Sorbent) | U42: DAC Hubs (Solvent) | V42: Rhodium $18B
...

Sheet Innovation Policy Scenarios
A1: Tech | B1: DAC (sorbent) | C1: DAC (solvent) | D1: TEW (Nature Paper) | E1: TEW (Ours) - less input costs | F1: OEW | G1: BECCS | L1: Baseline Parameters
A2: 2025 | B2: =(1-B14)*(1-B22)*B$10*EXP(B$11*($A2-$A$2+B30)) -> 446 | C2: =(1-C14)*(1-C22)*C$10*EXP(C$11*($A2-$A$2+C30)) -> 209 | D2: =(1-D14)*(1-D22)*D$10*EXP(D$11*($A2-$A$3+D30)) -> 316.03816 | E2: =(1-E14)*(1-E22)*E$10*EXP(E$11*($A2-$A$3+E30)) -> 269.98072 | F2: =(1-F14)*(1-F22)*F$10*EXP(F$11*($A2-$A$2+F30)) -> 140 | G2: =(1-G14)*(1-G22)*G$10*EXP(G$11*($A2-$A$2+G30)) -> 232 | L2: Tech | M2: DAC (sorbent) | N2: DAC (solvent) | O2: TEW (Nature Paper) | P2: TEW (Ours) - less input costs | Q2: OEW | R2: BECCS | S2: BECCS (implemented)
A3: 2030 | B3: =(1-B15)*(1-B23)*B$10*EXP(B$11*($A3-$A$2+B31)) -> 323.85932 | C3: =(1-C15)*(1-C23)*C$10*EXP(C$11*($A3-$A$2+C31)) -> 151.76367 | D3: =(1-D15)*(1-D23)*D$10*EXP(D$11*($A3-$A$3+D31)) -> 230.55795 | E3: =(1-E15)*(1-E23)*E$10*EXP(E$11*($A3-$A$3+E31)) -> 180.92669 | F3: =(1-F15)*(1-F23)*F$10*EXP(F$11*($A3-$A$2+F31)) -> 109.71153 | G3: =(1-G15)*(1-G23)*G$10*EXP(G$11*($A3-$A$2+G31)) -> 184.44636 | L3: 2025 | M3: ='Baseline Parameters'!B2 -> 446 | N3: ='Baseline Parameters'!C2 -> 209 | O3: ='Baseline Parameters'!D2 -> 316.03816 | P3: ='Baseline Parameters'!E2 -> 269.98072 | Q3: ='Baseline Parameters'!F2 -> 140 | R3: ='Baseline Parameters'!G2 -> 232 | S3: ='Baseline Parameters'!H2 -> 0.13945355
A4: 2035 | B4: =(1-B16)*(1-B24)*B$10*EXP(B$11*($A4-$A$2+B32)) -> 231.91485 | C4: =(1-C16)*(1-C24)*C$10*EXP(C$11*($A4-$A$2+C32)) -> 108.67759 | D4: =(1-D16)*(1-D24)*D$10*EXP(D$11*($A4-$A$3+D32)) -> 165.92431 | E4: =(1-E16)*(1-E24)*E$10*EXP(E$11*($A4-$A$3+E32)) -> 119.60845 | F4: =(1-F16)*(1-F24)*F$10*EXP(F$11*($A4-$A$2+F32)) -> 84.813667 | G4: =(1-G16)*(1-G24)*G$10*EXP(G$11*($A4-$A$2+G32)) -> 144.65769 | L4: 2030 | M4: ='Baseline Parameters'!B3 -> 380.16958 | N4: ='Baseline Parameters'!C3 -> 178.15122 | O4: ='Baseline Parameters'!D3 -> 265 | P4: ='Baseline Parameters'!E3 -> 207.95455 | Q4: ='Baseline Parameters'!F3 -> 126.10086 | R4: ='Baseline Parameters'!G3 -> 212 | S4: ='Baseline Parameters'!H3 -> 0.12743169
A5: 2040 | B5: =(1-B17)*(1-B25)*B$10*EXP(B$11*($A5-$A$2+B33)) -> 186.57432 | C5: =(1-C17)*(1-C25)*C$10*EXP(C$11*($A5-$A$2+C33)) -> 87.430566 | D5: =(1-D17)*(1-D25)*D$10*EXP(D$11*($A5-$A$3+D33)) -> 134.15012 | E5: =(1-E17)*(1-E25)*E$10*EXP(E$11*($A5-$A$3+E33)) -> 88.832574 | F5: =(1-F17)*(1-F25)*F$10*EXP(F$11*($A5-$A$2+F33)) -> 73.659805 | G5: =(1-G17)*(1-G25)*G$10*EXP(G$11*($A5-$A$2+G33)) -> 127.45712 | L5: 2035 | M5: ='Baseline Parameters'!B4 -> 324.05585 | N5: ='Baseline Parameters'!C4 -> 151.85577 | O5: ='Baseline Parameters'!D4 -> 222.20418 | P5: ='Baseline Parameters'!E4 -> 160.17845 | Q5: ='Baseline Parameters'!F4 -> 113.58162 | R5: ='Baseline Parameters'!G4 -> 193.72414 | S5: ='Baseline Parameters'!H4 -> 0.1164462
A6: 2045 | B6: =(1-B18)*(1-B26)*B$10*EXP(B$11*($A6-$A$2+B34)) -> 159.03561 | C6: =(1-C18)*(1-C26)*C$10*EXP(C$11*($A6-$A$2+C34)) -> 74.525654 | D6: =(1-D18)*(1-D26)*D$10*EXP(D$11*($A6-$A$3+D34)) -> 112.48573 | E6: =(1-E18)*(1-E26)*E$10*EXP(E$11*($A6-$A$3+E34)) -> 68.423914 | F6: =(1-F18)*(1-F26)*F$10*EXP(F$11*($A6-$A$2+F34)) -> 66.346891 | G6: =(1-G18)*(1-G26)*G$10*EXP(G$11*($A6-$A$2+G34)) -> 116.46944 | L6: 2040 | M6: ='Baseline Parameters'!B5 -> 276.22461 | N6: ='Baseline Parameters'!C5 -> 129.44158 | O6: ='Baseline Parameters'!D5 -> 186.31962 | P6: ='Baseline Parameters'!E5 -> 123.37857 | Q6: ='Baseline Parameters'!F5 -> 102.30529 | R6: ='Baseline Parameters'!G5 -> 177.02378 | S6: ='Baseline Parameters'!H5 -> 0.10640774
A7: 2050 | B7: =(1-B19)*(1-B27)*B$10*EXP(B$11*($A7-$A$2+B35)) -> 135.56166 | C7: =(1-C19)*(1-C27)*C$10*EXP(C$11*($A7-$A$2+C35)) -> 63.52553 | D7: =(1-D19)*(1-D27)*D$10*EXP(D$11*($A7-$A$3+D35)) -> 94.32 | E7: =(1-E19)*(1-E27)*E$10*EXP(E$11*($A7-$A$3+E35)) -> 52.704 | F7: =(1-F19)*(1-F27)*F$10*EXP(F$11*($A7-$A$2+F35)) -> 59.76 | G7: =(1-G19)*(1-G27)*G$10*EXP(G$11*($A7-$A$2+G35)) -> 106.42897 | L7: 2045 | M7: ='Baseline Parameters'!B6 -> 235.45335 | N7: ='Baseline Parameters'!C6 -> 110.33576 | O7: ='Baseline Parameters'!D6 -> 156.23018 | P7: ='Baseline Parameters'!E6 -> 95.033214 | Q7: ='Baseline Parameters'!F6 -> 92.14846 | R7: ='Baseline Parameters'!G6 -> 161.76311 | S7: ='Baseline Parameters'!H6 -> 0.097234657
L8: 2050 | M8: ='Baseline Parameters'!B7 -> 200.7 | N8: ='Baseline Parameters'!C7 -> 94.05 | O8: ='Baseline Parameters'!D7 -> 131 | P8: ='Baseline Parameters'!E7 -> 73.2 | Q8: ='Baseline Parameters'!F7 -> 83 | R8: ='Baseline Parameters'!G7 -> 147.81801 | S8: ='Baseline Parameters'!H7 -> 0.088852359
A10: A | B10: ='Baseline Parameters'!B13 -> 446 | C10: ='Baseline Parameters'!C13 -> 209 | D10: ='Baseline Parameters'!D13 -> 265 | E10: ='Baseline Parameters'!E13 -> 207.95455 | F10: ='Baseline Parameters'!F13 -> 140 | G10: ='Baseline Parameters'!G13 -> 232 | L10: Rhodium $6B
A11: B | B11: ='Baseline Parameters'!B14 -> -0.031940308 | C11: ='Baseline Parameters'!C14 -> -0.031940308 | D11: ='Baseline Parameters'!D14 -> -0.035226625 | E11: ='Baseline Parameters'!E14 -> -0.052206205 | F11: ='Baseline Parameters'!F14 -> -0.020912073 | G11: ='Baseline Parameters'!G14 -> -0.018030219 | L11: Tech | M11: DAC (sorbent) | N11: DAC (solvent) | O11: TEW (Nature Paper) | P11: TEW (Ours) - less input costs | Q11: OEW | R11: BECCS | S11: BECCS (implemented)
L12: 2025 | M12: =M3*(1-'Learning Rates'!$Q61) -> 446 | N12: =N3*(1-'Learning Rates'!$Q61) -> 209 | O12: =O3*(1-'Learning Rates'!$Q61) -> 316.03816 | P12: =P3*(1-'Learning Rates'!$Q61) -> 269.98072 | Q12: =Q3*(1-'Learning Rates'!$Q61) -> 140 | R12: =R3*(1-'Learning Rates'!$Q61) -> 232 | S12: =S3*(1-'Learning Rates'!$Q61) -> 0.13945355
A13: R&D Impact | B13: DAC (sorbent) | C13: DAC (solvent) | D13: TEW | E13: TEW | F13: OEW | G13: BECCS | H13: Units | L13: 2030 | M13: =M4*(1-'Learning Rates'!$Q62) -> 352.79537 | N13: =N4*(1-'Learning Rates'!$Q62) -> 165.32339 | O13: =O4*(1-'Learning Rates'!$Q62) -> 245.91861 | P13: =P4*(1-'Learning Rates'!$Q62) -> 192.98073 | Q13: =Q4*(1-'Learning Rates'!$Q62) -> 117.02093 | R13: =R4*(1-'Learning Rates'!$Q62) -> 196.73489 | S13: =S4*(1-'Learning Rates'!$Q62) -> 0.11825594
A14: 2025 | B14: 0 | C14: 0 | D14: 0 | E14: 0 | F14: 0 | G14: 0 | H14: Reduction in costs | L14: 2035 | M14: =M5*(1-'Learning Rates'!$Q63) -> 289.96846 | N14: =N5*(1-'Learning Rates'!$Q63) -> 135.88208 | O14: =O5*(1-'Learning Rates'!$Q63) -> 198.83056 | P14: =P5*(1-'Learning Rates'!$Q63) -> 143.3293 | Q14: =Q5*(1-'Learning Rates'!$Q63) -> 101.63399 | R14: =R5*(1-'Learning Rates'!$Q63) -> 173.34632 | S14: =S5*(1-'Learning Rates'!$Q63) -> 0.10419724
A15: 2030 | B15: 0.0333 | C15: 0.0333 | D15: 0.0333 | E15: 0.0333 | F15: 0.0333 | G15: 0.0333 | H15: Reduction in costs | L15: 2040 | M15: =M6*(1-'Learning Rates'!$Q64) -> 247.16858 | N15: =N6*(1-'Learning Rates'!$Q64) -> 115.82564 | O15: =O6*(1-'Learning Rates'!$Q64) -> 166.72068 | P15: =P6*(1-'Learning Rates'!$Q64) -> 110.4004 | Q15: =Q6*(1-'Learning Rates'!$Q64) -> 91.543807 | R15: =R6*(1-'Learning Rates'!$Q64) -> 158.40267 | S15: =S6*(1-'Learning Rates'!$Q64) -> 0.095214723
A16: 2035 | B16: 0.0666 | C16: 0.0666 | D16: 0.0666 | E16: 0.0666 | F16: 0.0666 | G16: 0.0666 | H16: Reduction in costs | L16: 2045 | M16: =M7*(1-'Learning Rates'!$Q65) -> 210.68604 | N16: =N7*(1-'Learning Rates'!$Q65) -> 98.729559 | O16: =O7*(1-'Learning Rates'!$Q65) -> 139.79635 | P16: =P7*(1-'Learning Rates'!$Q65) -> 85.036683 | Q16: =Q7*(1-'Learning Rates'!$Q65) -> 82.455376 | R16: =R7*(1-'Learning Rates'!$Q65) -> 144.74727 | S16: =S7*(1-'Learning Rates'!$Q65) -> 0.087006557
A17: 2040 | B17: 0.1 | C17: 0.1 | D17: 0.1 | E17: 0.1 | F17: 0.1 | G17: 0.1 | H17: Reduction in costs | L17: 2050 | M17: =M8*(1-'Learning Rates'!$Q66) -> 179.5884 | N17: =N8*(1-'Learning Rates'!$Q66) -> 84.156894 | O17: =O8*(1-'Learning Rates'!$Q66) -> 117.22013 | P17: =P8*(1-'Learning Rates'!$Q66) -> 65.500102 | Q17: =Q8*(1-'Learning Rates'!$Q66) -> 74.269242 | R17: =R8*(1-'Learning Rates'!$Q66) -> 132.26906 | S17: =S8*(1-'Learning Rates'!$Q66) -> 0.079505992
A18: 2045 | B18: 0.1 | C18: 0.1 | D18: 0.1 | E18: 0.1 | F18: 0.1 | G18: 0.1 | H18: Reduction in costs
A19: 2050 | B19: 0.1 | C19: 0.1 | D19: 0.1 | E19: 0.1 | F19: 0.1 | G19: 0.1 | H19: Reduction in costs | L19: Maintain Current Appropriations
L20: Tech | M20: DAC (sorbent) | N20: DAC (solvent) | O20: TEW (Nature Paper) | P20: TEW (Ours) - less input costs | Q20: OEW | R20: BECCS | S20: BECCS (implemented)
A21: Pilot & Demonstrations Impact | B21: DAC (sorbent) | C21: DAC (solvent) | D21: TEW | E21: TEW | F21: OEW | G21: BECCS | H21: Units | L21: 2025 | M21: =M3*(1-'Learning Rates'!$R61) -> 436.367 | N21: =N3*(1-'Learning Rates'!$R61) -> 204.48588 | O21: =O3*(1-'Learning Rates'!$R61) -> 309.21216 | P21: =P3*(1-'Learning Rates'!$R61) -> 264.1495 | Q21: =Q3*(1-'Learning Rates'!$R61) -> 136.97619 | R21: =R3*(1-'Learning Rates'!$R61) -> 226.98911 | S21: =S3*(1-'Learning Rates'!$R61) -> 0.13644154
A22: 2025 | B22: 0 | C22: 0 | D22: 0 | E22: 0 | F22: 0 | G22: 0 | H22: Reduction in costs | L22: 2030 | M22: =M4*(1-'Learning Rates'!$R62) -> 365.74754 | N22: =N4*(1-'Learning Rates'!$R62) -> 171.3929 | O22: =O4*(1-'Learning Rates'!$R62) -> 254.94701 | P22: =P4*(1-'Learning Rates'!$R62) -> 200.06562 | Q22: =Q4*(1-'Learning Rates'!$R62) -> 121.31712 | R22: =R4*(1-'Learning Rates'!$R62) -> 203.95761 | S22: =S4*(1-'Learning Rates'!$R62) -> 0.12259747
A23: 2030 | B23: 0.1 | C23: 0.1 | D23: 0.1 | E23: 0.1 | F23: 0.1 | G23: 0.1 | H23: Reduction in costs | L23: 2035 | M23: =M5*(1-'Learning Rates'!$R63) -> 307.51791 | N23: =N5*(1-'Learning Rates'!$R63) -> 144.10592 | O23: =O5*(1-'Learning Rates'!$R63) -> 210.86416 | P23: =P5*(1-'Learning Rates'!$R63) -> 152.00386 | Q23: =Q5*(1-'Learning Rates'!$R63) -> 107.78507 | R23: =R5*(1-'Learning Rates'!$R63) -> 183.83757 | S23: =S5*(1-'Learning Rates'!$R63) -> 0.11050346
A24: 2035 | B24: 0.2 | C24: 0.2 | D24: 0.2 | E24: 0.2 | F24: 0.2 | G24: 0.2 | H24: Reduction in costs | L24: 2040 | M24: =M6*(1-'Learning Rates'!$R64) -> 259.11455 | N24: =N6*(1-'Learning Rates'!$R64) -> 121.42364 | O24: =O6*(1-'Learning Rates'!$R64) -> 174.77851 | P24: =P6*(1-'Learning Rates'!$R64) -> 115.73619 | Q24: =Q6*(1-'Learning Rates'!$R64) -> 95.968236 | R24: =R6*(1-'Learning Rates'!$R64) -> 166.05848 | S24: =S6*(1-'Learning Rates'!$R64) -> 0.099816572
A25: 2040 | B25: 0.2 | C25: 0.2 | D25: 0.2 | E25: 0.2 | F25: 0.2 | G25: 0.2 | H25: Reduction in costs | L25: 2045 | M25: =M7*(1-'Learning Rates'!$R65) -> 218.67177 | N25: =N7*(1-'Learning Rates'!$R65) -> 102.47175 | O25: =O7*(1-'Learning Rates'!$R65) -> 145.09511 | P25: =P7*(1-'Learning Rates'!$R65) -> 88.259866 | Q25: =Q7*(1-'Learning Rates'!$R65) -> 85.580719 | R25: =R7*(1-'Learning Rates'!$R65) -> 150.23369 | S25: =S7*(1-'Learning Rates'!$R65) -> 0.090304404
A26: 2045 | B26: 0.2 | C26: 0.2 | D26: 0.2 | E26: 0.2 | F26: 0.2 | G26: 0.2 | H26: Reduction in costs | L26: 2050 | M26: =M8*(1-'Learning Rates'!$R66) -> 184.76128 | N26: =N8*(1-'Learning Rates'!$R66) -> 86.580957 | O26: =O8*(1-'Learning Rates'!$R66) -> 120.59655 | P26: =P8*(1-'Learning Rates'!$R66) -> 67.386773 | Q26: =Q8*(1-'Learning Rates'!$R66) -> 76.4085 | R26: =R8*(1-'Learning Rates'!$R66) -> 136.07895 | S26: =S8*(1-'Learning Rates'!$R66) -> 0.081796089
A27: 2050 | B27: 0.2 | C27: 0.2 | D27: 0.2 | E27: 0.2 | F27: 0.2 | G27: 0.2 | H27: Reduction in costs
L28: Triple Appropriations
A29: Hubs | B29: DAC (sorbent) | C29: DAC (solvent) | D29: TEW | E29: TEW | F29: OEW | G29: BECCS | H29: Units | L29: Tech | M29: DAC (sorbent) | N29: DAC (solvent) | O29: TEW (Nature Paper) | P29: TEW (Ours) - less input costs | Q29: OEW | R29: BECCS | S29: BECCS (implemented)
A30: 2025 | B30: 0 | C30: 0 | D30: 0 | E30: 0 | F30: 0 | G30: 0 | H30: Number of years of acceleration for cost decreases | L30: 2025 | M30: =M3*(1-'Learning Rates'!$S61) -> 423.23873 | N30: =N3*(1-'Learning Rates'!$S61) -> 198.33384 | O30: =O3*(1-'Learning Rates'!$S61) -> 299.90939 | P30: =P3*(1-'Learning Rates'!$S61) -> 256.20246 | Q30: =Q3*(1-'Learning Rates'!$S61) -> 132.85521 | R30: =R3*(1-'Learning Rates'!$S61) -> 220.16006 | S30: =S3*(1-'Learning Rates'!$S61) -> 0.13233665
A31: 2030 | B31: 0.66 | C31: 0.66 | D31: 0 | E31: 0 | F31: 0 | G31: 0 | H31: Number of years of acceleration for cost decreases | L31: 2030 | M31: =M4*(1-'Learning Rates'!$S62) -> 349.97816 | N31: =N4*(1-'Learning Rates'!$S62) -> 164.00322 | O31: =O4*(1-'Learning Rates'!$S62) -> 243.95485 | P31: =P4*(1-'Learning Rates'!$S62) -> 191.4397 | Q31: =Q4*(1-'Learning Rates'!$S62) -> 116.08648 | R31: =R4*(1-'Learning Rates'!$S62) -> 195.16388 | S31: =S4*(1-'Learning Rates'!$S62) -> 0.11731162
A32: 2035 | B32: 1.33 | C32: 1.33 | D32: 0 | E32: 0 | F32: 0 | G32: 0 | H32: Number of years of acceleration for cost decreases | L32: 2035 | M32: =M5*(1-'Learning Rates'!$S63) -> 291.98474 | N32: =N5*(1-'Learning Rates'!$S63) -> 136.82693 | O32: =O5*(1-'Learning Rates'!$S63) -> 200.21311 | P32: =P5*(1-'Learning Rates'!$S63) -> 144.32593 | Q32: =Q5*(1-'Learning Rates'!$S63) -> 102.34069 | R32: =R5*(1-'Learning Rates'!$S63) -> 174.55168 | S32: =S5*(1-'Learning Rates'!$S63) -> 0.10492177
A33: 2040 | B33: 2 | C33: 2 | D33: 0 | E33: 0 | F33: 0 | G33: 0 | H33: Number of years of acceleration for cost decreases | L33: 2040 | M33: =M6*(1-'Learning Rates'!$S64) -> 244.78495 | N33: =N6*(1-'Learning Rates'!$S64) -> 114.70864 | O33: =O6*(1-'Learning Rates'!$S64) -> 165.11287 | P33: =P6*(1-'Learning Rates'!$S64) -> 109.33573 | Q33: =Q6*(1-'Learning Rates'!$S64) -> 90.660982 | R33: =R6*(1-'Learning Rates'!$S64) -> 156.87508 | S33: =S6*(1-'Learning Rates'!$S64) -> 0.094296497
A34: 2045 | B34: 2 | C34: 2 | D34: 0 | E34: 0 | F34: 0 | G34: 0 | H34: Number of years of acceleration for cost decreases | L34: 2045 | M34: =M7*(1-'Learning Rates'!$S65) -> 205.84332 | N34: =N7*(1-'Learning Rates'!$S65) -> 96.46021 | O34: =O7*(1-'Learning Rates'!$S65) -> 136.58306 | P34: =P7*(1-'Learning Rates'!$S65) -> 83.082073 | Q34: =Q7*(1-'Learning Rates'!$S65) -> 80.560098 | R34: =R7*(1-'Learning Rates'!$S65) -> 141.42018 | S34: =S7*(1-'Learning Rates'!$S65) -> 0.085006667
A35: 2050 | B35: 2 | C35: 2 | D35: 0 | E35: 0 | F35: 0 | G35: 0 | H35: Number of years of acceleration for cost decreases | L35: 2050 | M35: =M8*(1-'Learning Rates'!$S66) -> 173.46149 | N35: =N8*(1-'Learning Rates'!$S66) -> 81.285765 | O35: =O8*(1-'Learning Rates'!$S66) -> 113.221 | P35: =P8*(1-'Learning Rates'!$S66) -> 63.265476 | Q35: =Q8*(1-'Learning Rates'!$S66) -> 71.735444 | R35: =R8*(1-'Learning Rates'!$S66) -> 127.75652 | S35: =S8*(1-'Learning Rates'!$S66) -> 0.076793535
L37: DAC Hubs
L38: Tech | M38: DAC (sorbent) | N38: DAC (solvent) | O38: TEW (Nature Paper) | P38: TEW (Ours) - less input costs | Q38: OEW | R38: BECCS | S38: BECCS (implemented)
L39: 2025 | M39: =M12*(1-'Learning Rates'!T61) -> 410.81266 | N39: =N12*(1-'Learning Rates'!U61) -> 192.51086 | O39: =O12 -> 316.03816 | P39: =P12 -> 269.98072 | Q39: =Q12 -> 140 | R39: =R12 -> 232 | S39: =S12 -> 0.13945355
L40: 2030 | M40: =M13*(1-'Learning Rates'!T62) -> 324.96144 | N40: =N13*(1-'Learning Rates'!U62) -> 152.28014 | O40: =O13 -> 245.91861 | P40: =P13 -> 192.98073 | Q40: =Q13 -> 117.02093 | R40: =R13 -> 196.73489 | S40: =S13 -> 0.11825594
L41: 2035 | M41: =M14*(1-'Learning Rates'!T63) -> 267.09128 | N41: =N14*(1-'Learning Rates'!U63) -> 125.16161 | O41: =O14 -> 198.83056 | P41: =P14 -> 143.3293 | Q41: =Q14 -> 101.63399 | R41: =R14 -> 173.34632 | S41: =S14 -> 0.10419724
L42: 2040 | M42: =M15*(1-'Learning Rates'!T64) -> 227.66812 | N42: =N15*(1-'Learning Rates'!U64) -> 106.68753 | O42: =O15 -> 166.72068 | P42: =P15 -> 110.4004 | Q42: =Q15 -> 91.543807 | R42: =R15 -> 158.40267 | S42: =S15 -> 0.095214723
...

Sheet verify-2025
A1: Tech | B1: DAC (sorbent) | C1: DAC (solvent) | D1: TEW | E1: OEW | F1: BECCS | G1: BECCS | I1: Nothing | J1: Low | K1: High | L1: Very High
A2: 2025 | B2: 446 | C2: 209 | D2: =D$13*EXP(D$14*($A2-$A$3)) -> 316.03816 | E2: 140 | F2: 301 | G2: =F2/6.1/1000*44/12 -> 0.18092896 | I2: 13.5 | J2: 13.5 | K2: 13.5 | L2: 13.5
A3: 2030 | B3: =B$13*EXP(B$14*($A3-$A$2)) -> 380.16958 | C3: =C$13*EXP(C$14*($A3-$A$2)) -> 178.15122 | D3: 265 | E3: =E$13*EXP(E$14*($A3-$A$2)) -> 126.10086 | F3: 265 | G3: =F3/6.1/1000*44/12 -> 0.15928962 | I3: =I$13*EXP(I$14*($A3-$A$2)) -> 20.149627 | J3: =J$13*EXP(J$14*($A3-$A$2)) -> 27.801038 | K3: =K$13*EXP(K$14*($A3-$A$2)) -> 34.632614 | L3: =L$13*EXP(L$14*($A3-$A$2)) -> 38.046023
A4: 2035 | B4: =B$13*EXP(B$14*($A4-$A$2)) -> 324.05585 | C4: =C$13*EXP(C$14*($A4-$A$2)) -> 151.85577 | D4: =D$13*EXP(D$14*($A4-$A$3)) -> 222.20418 | E4: =E$13*EXP(E$14*($A4-$A$2)) -> 113.58162 | F4: =F$13*EXP(F$14*($A4-$A$2)) -> 233.30565 | G4: =F4/6.1/1000*44/12 -> 0.14023837 | I4: =I$13*EXP(I$14*($A4-$A$2)) -> 30.074628 | J4: =J$13*EXP(J$14*($A4-$A$2)) -> 57.251684 | K4: =K$13*EXP(K$14*($A4-$A$2)) -> 88.845772 | L4: =L$13*EXP(L$14*($A4-$A$2)) -> 107.22221
A5: 2040 | B5: =B$13*EXP(B$14*($A5-$A$2)) -> 276.22461 | C5: =C$13*EXP(C$14*($A5-$A$2)) -> 129.44158 | D5: =D$13*EXP(D$14*($A5-$A$3)) -> 186.31962 | E5: =E$13*EXP(E$14*($A5-$A$2)) -> 102.30529 | F5: =F$13*EXP(F$14*($A5-$A$2)) -> 205.40198 | G5: =F5/6.1/1000*44/12 -> 0.12346567 | I5: =I$13*EXP(I$14*($A5-$A$2)) -> 44.888336 | J5: =J$13*EXP(J$14*($A5-$A$2)) -> 117.90046 | K5: =K$13*EXP(K$14*($A5-$A$2)) -> 227.92306 | L5: =L$13*EXP(L$14*($A5-$A$2)) -> 302.1762
A6: 2045 | B6: =B$13*EXP(B$14*($A6-$A$2)) -> 235.45335 | C6: =C$13*EXP(C$14*($A6-$A$2)) -> 110.33576 | D6: =D$13*EXP(D$14*($A6-$A$3)) -> 156.23018 | E6: =E$13*EXP(E$14*($A6-$A$2)) -> 92.14846 | F6: =F$13*EXP(F$14*($A6-$A$2)) -> 180.83563 | G6: =F6/6.1/1000*44/12 -> 0.10869901 | I6: =I$13*EXP(I$14*($A6-$A$2)) -> 66.998758 | J6: =J$13*EXP(J$14*($A6-$A$2)) -> 242.79669 | K6: =K$13*EXP(K$14*($A6-$A$2)) -> 584.70898 | L6: =L$13*EXP(L$14*($A6-$A$2)) -> 851.60018
A7: 2050 | B7: =B2*B17 -> 200.7 | C7: =C2*C17 -> 94.05 | D7: 131 | E7: 83 | F7: =F$13*EXP(F$14*($A7-$A$2)) -> 159.20745 | G7: =F7/6.1/1000*44/12 -> 0.095698467 | I7: 100 | J7: 500 | K7: 1500 | L7: 2400
A8: Source | B8: R2R | C8: R2R | D8: https://www.nature.com/articles/s41586-024-08429-2.pdf | E8: https://iopscience.iop.org/article/10.1088/1748-9326/ad5192/pdf | F8: CDR Price Survey White Paper-Email.pdf | I8: N/A | J8: N/A | K8: N/A | L8: N/A
A9: Page | B9: 7-11 | C9: 7-11 | D9: 432 | E9: 8 | F9: 4
A10: Notes | B10: Less heat and electric | C10: Less heat and electric | D10: Illinois 2030 and 2050 | E10: Fixed costs (low-carbon scenario
A11: Units | B11: 2025$/t CO2-eq | C11: 2025$/t CO2-eq | D11: 2025$/t CO2-eq | E11: 2025$/t CO2-eq | F11: 2025$/t CO2-eq | G11: 1975 USD/t C | I11: Mt CO2-eq | J11: Mt CO2-eq | K11: Mt CO2-eq
A13: A | B13: =EXP(LN(B2)-B14*0) -> 446 | C13: =EXP(LN(C2)-C14*0) -> 209 | D13: =EXP(LN(D3)-D14*0) -> 265 | E13: =EXP(LN(E2)-E14*0) -> 140 | F13: =EXP(LN(F2)-F14*0) -> 301 | I13: =EXP(LN(I2)-I14*0) -> 13.5 | J13: =EXP(LN(J2)-J14*0) -> 13.5 | K13: =EXP(LN(K2)-K14*0) -> 13.5 | L13: =EXP(LN(L2)-L14*0) -> 13.5
A14: B | B14: =(LN(B2)-LN(B7))/($A2-$A7) -> -0.031940308 | C14: =(LN(C2)-LN(C7))/($A2-$A7) -> -0.031940308 | D14: =(LN(D3)-LN(D7))/($A3-$A7) -> -0.035226625 | E14: =(LN(E2)-LN(E7))/($A2-$A7) -> -0.020912073 | F14: =(LN(F2)-LN(F3))/($A2-$A3) -> -0.025476088 | I14: =(LN(I2)-LN(I7))/($A2-$A7) -> 0.08009922 | J14: =(LN(J2)-LN(J7))/($A2-$A7) -> 0.14447674 | K14: =(LN(K2)-LN(K7))/($A2-$A7) -> 0.18842123 | L14: =(LN(L2)-LN(L7))/($A2-$A7) -> 0.20722137
A17: Ultimate reduction in cost | B17: 0.45 | C17: 0.45 | H17: 2025 source | I17: Rhodium 2024 | J17: Rhodium 2024 | K17: Rhodium 2024
A18: Years | B18: 25 | C18: 25 | H18: Page | I18: 42 | J18: 42 | K18: 42
A19: Source | B19: Rhodium 2024 | C19: Rhodium 2024
A20: Page | B20: 44 | C20: 44

Sheet Procurement
A1: LOW | B1: Scaling | C1: 3B | D1: Rhodium | I1: CDR (USD)
A2: Year | B2: CDR (Mt) | C2: CDR (Mt) | D2: CDR (Mt) | I2: Year | J2: Avg. Price CDR (Low scenario) | K2: 3B (Million USD) | L2: Rhodium (Million)
A3: 2025 | B3: 0.05 | C3: =K3/$J3 -> 9.1538218 | D3: =L3/$J3 -> 0 | I3: =A3 -> 2025 | J3: 360.50516 | K3: 3300 | L3: 0
A4: 2030 | B4: 5 | C4: =K4/$J4 -> 11.117979 | D4: =L4/$J4 -> 67.381688 | I4: =A4 -> 2030 | J4: 296.81655 | K4: 3300 | L4: 20000
A5: 2035 | B5: 10 | C5: =K5/$J5 -> 14.945047 | D5: =L5/$J5 -> 158.50807 | I5: =A5 -> 2035 | J5: 220.80895 | K5: 3300 | L5: =(L4+L6)/2 -> 35000
A6: 2040 | B6: 0 | C6: =K6/$J6 -> 0 | D6: =L6/$J6 -> 246.90691 | I6: =A6 -> 2040 | J6: 202.50547 | K6: 0 | L6: 50000
A7: 2045 | B7: 0 | C7: =K7/$J7 -> 0 | D7: =L7/$J7 -> 406.17138 | I7: =A7 -> 2045 | J7: 184.65112 | K7: 0 | L7: =(L6+L8)/2 -> 75000
A8: 2050 | B8: 0 | C8: =K8/$J8 -> 0 | D8: =L8/$J8 -> 578.25596 | I8: =A8 -> 2050 | J8: 172.9338 | K8: 0 | L8: 100000
A9: Source | B9: https://www.congress.gov/bill/118th-congress/senate-bill/3615/text | J9: Low baseline scenario | K9: EFI (2022) | L9: Rhodium (2024)
A12: HIGH | B12: Scaling | C12: 3B | D12: Rhodium | I12: CDR (USD)
A13: Year | B13: CDR (Mt) | C13: CDR (Mt) | D13: CDR (Mt) | I13: Year | J13: Avg. Price CDR (Low scenario) | K13: 3B (Million USD) | L13: Rhodium (Million)
A14: 2025 | B14: 0.05 | C14: =K14/$J14 -> 9.1527705 | D14: =L14/$J14 -> 0 | I14: =A14 -> 2025 | J14: 360.54657 | K14: 3300 | L14: 0
A15: 2030 | B15: 5 | C15: =K15/$J15 -> 11.123318 | D15: =L15/$J15 -> 67.414047 | I15: =A15 -> 2030 | J15: 296.67408 | K15: 3300 | L15: 20000
A16: 2035 | B16: 10 | C16: =K16/$J16 -> 14.849857 | D16: =L16/$J16 -> 157.49848 | I16: =A16 -> 2035 | J16: 222.22436 | K16: 3300 | L16: =(L15+L17)/2 -> 35000
A17: 2040 | B17: 0 | C17: =K17/$J17 -> 0 | D17: =L17/$J17 -> 243.06758 | I17: =A17 -> 2040 | J17: 205.70411 | K17: 0 | L17: 50000
A18: 2045 | B18: 0 | C18: =K18/$J18 -> 0 | D18: =L18/$J18 -> 380.4752 | I18: =A18 -> 2045 | J18: 197.12192 | K18: 0 | L18: =(L17+L19)/2 -> 75000
A19: 2050 | B19: 0 | C19: =K19/$J19 -> 0 | D19: =L19/$J19 -> 474.18677 | I19: =A19 -> 2050 | J19: 210.88737 | K19: 0 | L19: 100000
A20: Source | B20: https://www.congress.gov/bill/118th-congress/senate-bill/3615/text | J20: Low baseline scenario | K20: EFI (2022) | L20: Rhodium (2024)
